Workbook

Sheet 기준가격대장(결산후)
A1: Column4 | B1: Column1 | C1: Column2 | D1: Column3 | E1: Column5 | F1: Column6 | G1: Column7 | H1: Column8
C2: 차변 | G2: 대변
A3: 코드 | B3: 당일잔액 | C3: 당일증감액 | D3: 전일잔액 | E3: 계정명 | F3: 전일잔액 | G3: 당일증감액 | H3: 당일잔액
A4: 100000 | B4: 153189360965 | C4: 35100224209 | D4: 153187595708 | E4: 자산합계 | F4: 0 | G4: 35098458952 | H4: 0
A5: 101010 | B5: 7196301321 | C5: 0 | D5: 7196301321 | E5: 예금 | F5: 0 | G5: 0 | H5: 0
A6: 111010 | B6: 106485058475 | C6: 33658782896 | D6: 73217869377 | E6: 상장주식 | F6: 0 | G6: 391593798 | H6: 0
A7: 113010 | B7: 5368673944 | C7: 1765255 | D7: 5366908689 | E7: 국채 | F7: 0 | G7: 0 | H7: 0
A8: 115010 | B8: 24463760580 | C8: 1046317003 | D8: 23417443577 | E8: 상장펀드 | F8: 0 | G8: 0 | H8: 0
A9: 139310 | B9: 8837106649 | C9: 0 | D9: 8837106649 | E9: 상장펀드미수입금 | F9: 0 | G9: 0 | H9: 0
A10: 139410 | B10: 584987500 | C10: 0 | D10: 584987500 | E10: 선물미수입금 | F10: 0 | G10: 0 | H10: 0
A11: 139810 | B11: 455343 | C11: 0 | D11: 455343 | E11: 대차거래미수입금 | F11: 0 | G11: 0 | H11: 0
A12: 147010 | B12: 221852625 | C12: 0 | D12: 221852625 | E12: 주식미수배당금 | F12: 0 | G12: 0 | H12: 0
A13: 149010 | B13: 661948 | C13: 0 | D13: 661948 | E13: 채권미수이자 | F13: 0 | G13: 0 | H13: 0
A14: 149110 | B14: 6231172 | C14: 0 | D14: 6231172 | E14: 예금미수이자 | F14: 0 | G14: 0 | H14: 0
A15: 151010 | B15: 24271408 | C15: 0 | D15: 24271408 | E15: 채권기경과이자 | F15: 0 | G15: 0 | H15: 0
... A78: 531012 | B78: 0 | C78: 33658782896 | D78: 0 | E78: 상장주식평가이익(비과세) | F78: 33658782896 | G78: 0 | H78: 0
A79: 533011 | B79: 0 | C79: 1765255 | D79: 0 | E79: 채권평가이익(과세) | F79: 1765255 | G79: 0 | H79: 0 | L79: 167470000000
A80: 537011 | B80: 0 | C80: 29549335 | D80: 0 | E80: 상장펀드평가이익(과세) | F80: 29549335 | G80: 0 | H80: 0
A81: 537012 | B81: 0 | C81: 1016767668 | D81: 0 | E81: 상장펀드평가이익(비과세) | F81: 1016767668 | G81: 0 | H81: 0
A82: 555011 | B82: 0 | C82: 831697 | D82: 0 | E82: 채권상환이익(과세) | F82: 831697 | G82: 0 | H82: 0
A83: 557011 | B83: 0 | C83: 928953970 | D83: 0 | E83: 주식수입배당금(과세) | F83: 928953970 | G83: 0 | H83: 0
A84: 557012 | B84: 0 | C84: 19589055 | D84: 0 | E84: 주식수입배당금(비과세) | F84: 19589055 | G84: 0 | H84: 0
A85: 557051 | B85: 0 | C85: 312007724 | D85: 0 | E85: 상장펀드수입배당금(과세) | F85: 312007724 | G85: 0 | H85: 0
A86: 557052 | B86: 0 | C86: 28135256 | D86: 0 | E86: 상장펀드수입배당금(비과세) | F86: 28135256 | G86: 0 | H86: 0 | L86: 24645700000000
A87: 559011 | B87: 0 | C87: 3000 | D87: 0 | E87: 주식배당액(과세) | F87: 3000 | G87: 0 | H87: 0
A88: 561011 | B88: 0 | C88: 661948 | D88: 0 | E88: 채권수입이자(과세) | F88: 661948 | G88: 0 | H88: 0
A89: 561111 | B89: 0 | C89: 87439722 | D89: 0 | E89: 예금수입이자(과세) | F89: 87439722 | G89: 0 | H89: 0
A90: 561211 | B90: 0 | C90: 1842187 | D90: 0 | E90: REPO수입이자(과세) | F90: 1842187 | G90: 0 | H90: 0
A91: 561231 | B91: 0 | C91: 3137321 | D91: 0 | E91: 위탁증거금수입이자(과세) | F91: 3137321 | G91: 0 | H91: 0
A92: 565031 | B92: 0 | C92: 5121934 | D92: 0 | E92: 대차거래수입수수료(과세) | F92: 5121934 | G92: 0 | H92: 0
A93: 567011 | B93: 0 | C93: 5890881 | D93: 0 | E93: 단주대금수령액(과세) | F93: 5890881 | G93: 0 | H93: 0
A94: 567012 | B94: 0 | C94: 643877 | D94: 0 | E94: 단주대금수령액(비과세) | F94: 643877 | G94: 0 | H94: 0
A95: 567111 | B95: 0 | C95: 3557 | D95: 0 | E95: 기타이익(과세) | F95: 3557 | G95: 0 | H95: 0
A96: 600000 | B96: 153189360965 | C96: 789450783835 | D96: 232508639335 | E96: 총합계 | F96: 232508639335 | G96: 789450783835 | H96: 153189360965
A97: 700001 | B97: 0 | C97: 0 | D97: 0 | E97: 순자산총액 | F97: 137368956901 | G97: 0 | H97: 137368956901
A98: 700002 | B98: 0 | C98: 0 | D98: 0 | E98: 과세순자산총액 | F98: 37354536107 | G98: 0 | H98: 37354536107
... A125: 700039 | B125: 0 | C125: 0 | D125: 0 | E125: 발행 CU수량 | F125: 29 | G125: 0 | H125: 29

Sheet 통합기준가격대장(결산후)
B2: 자산검증 | C2: =SUM(B7:B91)=B6 -> TRUE | D2: 부채검증 | E2: =SUM(I93:I146)=I92 -> TRUE | F2: 자본검증 | G2: =SUM(I148:I159)=I147 -> TRUE
B3: 비용검증 | C3: =SUM(D161:D262)=D160 -> TRUE | D3: 수익검증 | E3: =SUM(G264:G366)=G263 -> TRUE
B5: 당일잔액 | C5: 당일증감액 | D5: 전일잔액 | E5: 코드 | F5: 계정명 | G5: 전일잔액 | H5: 당일증감액 | I5: 당일잔액
B6: =IFERROR(VLOOKUP(E6,'기준가격대장(결산후)'!$A$4:$H$500,2,0),0) -> 153189360965 | C6: =IFERROR(VLOOKUP(E6,'기준가격대장(결산후)'!$A$4:$H$500,3,0),0) -> 35100224209 | D6: =IFERROR(VLOOKUP(E6,'기준가격대장(결산후)'!$A$4:$H$500,4,0),0) -> 153187595708 | E6: 100000 | F6: 자산합계 | G6: =IFERROR(VLOOKUP(E6,'기준가격대장(결산후)'!$A$4:$H$500,6,0),0) -> 0 | H6: =IFERROR(VLOOKUP(E6,'기준가격대장(결산후)'!$A$4:$H$500,7,0),0) -> 35098458952 | I6: =IFERROR(VLOOKUP(E6,'기준가격대장(결산후)'!$A$4:$H$500,8,0),0) -> 0
B7: =IFERROR(VLOOKUP(E7,'기준가격대장(결산후)'!$A$4:$H$500,2,0),0) -> 7196301321 | C7: =IFERROR(VLOOKUP(E7,'기준가격대장(결산후)'!$A$4:$H$500,3,0),0) -> 0 | D7: =IFERROR(VLOOKUP(E7,'기준가격대장(결산후)'!$A$4:$H$500,4,0),0) -> 7196301321 | E7: 101010 | F7: 예금 | G7: =IFERROR(VLOOKUP(E7,'기준가격대장(결산후)'!$A$4:$H$500,6,0),0) -> 0 | H7: =IFERROR(VLOOKUP(E7,'기준가격대장(결산후)'!$A$4:$H$500,7,0),0) -> 0 | I7: =IFERROR(VLOOKUP(E7,'기준가격대장(결산후)'!$A$4:$H$500,8,0),0) -> 0 | K7: 자산검증 | L7: =SUM(B7:B91)=B6 -> TRUE | M7: =SUM(B7:B91)-B6 -> 0
B8: =IFERROR(VLOOKUP(E8,'기준가격대장(결산후)'!$A$4:$H$500,2,0),0) -> 0 | C8: =IFERROR(VLOOKUP(E8,'기준가격대장(결산후)'!$A$4:$H$500,3,0),0) -> 0 | D8: =IFERROR(VLOOKUP(E8,'기준가격대장(결산후)'!$A$4:$H$500,4,0),0) -> 0 | E8: 101050 | F8: 외화예금 | G8: =IFERROR(VLOOKUP(E8,'기준가격대장(결산후)'!$A$4:$H$500,6,0),0) -> 0 | H8: =IFERROR(VLOOKUP(E8,'기준가격대장(결산후)'!$A$4:$H$500,7,0),0) -> 0 | I8: =IFERROR(VLOOKUP(E8,'기준가격대장(결산후)'!$A$4:$H$500,8,0),0) -> 0 | L8: <<FALSE 나오면 조서에 없는 계정이 해당펀드 기준가격대장에 있으므로 추가해야함
B9: =IFERROR(VLOOKUP(E9,'기준가격대장(결산후)'!$A$4:$H$500,2,0),0) -> 0 | C9: =IFERROR(VLOOKUP(E9,'기준가격대장(결산후)'!$A$4:$H$500,3,0),0) -> 0 | D9: =IFERROR(VLOOKUP(E9,'기준가격대장(결산후)'!$A$4:$H$500,4,0),0) -> 0 | E9: 103010 | F9: 콜론 | G9: =IFERROR(VLOOKUP(E9,'기준가격대장(결산후)'!$A$4:$H$500,6,0),0) -> 0 | H9: =IFERROR(VLOOKUP(E9,'기준가격대장(결산후)'!$A$4:$H$500,7,0),0) -> 0 | I9: =IFERROR(VLOOKUP(E9,'기준가격대장(결산후)'!$A$4:$H$500,8,0),0) -> 0
B10: =IFERROR(VLOOKUP(E10,'기준가격대장(결산후)'!$A$4:$H$500,2,0),0) -> 0 | C10: =IFERROR(VLOOKUP(E10,'기준가격대장(결산후)'!$A$4:$H$500,3,0),0) -> 0 | D10: =IFERROR(VLOOKUP(E10,'기준가격대장(결산후)'!$A$4:$H$500,4,0),0) -> 0 | E10: 105010 | F10: CP/전단채 | G10: =IFERROR(VLOOKUP(E10,'기준가격대장(결산후)'!$A$4:$H$500,6,0),0) -> 0 | H10: =IFERROR(VLOOKUP(E10,'기준가격대장(결산후)'!$A$4:$H$500,7,0),0) -> 0 | I10: =IFERROR(VLOOKUP(E10,'기준가격대장(결산후)'!$A$4:$H$500,8,0),0) -> 0 | K10: VLOOKUP 참조 절대값 잘걸기
B11: =IFERROR(VLOOKUP(E11,'기준가격대장(결산후)'!$A$4:$H$500,2,0),0) -> 0 | C11: =IFERROR(VLOOKUP(E11,'기준가격대장(결산후)'!$A$4:$H$500,3,0),0) -> 0 | D11: =IFERROR(VLOOKUP(E11,'기준가격대장(결산후)'!$A$4:$H$500,4,0),0) -> 0 | E11: 107010 | F11: CD | G11: =IFERROR(VLOOKUP(E11,'기준가격대장(결산후)'!$A$4:$H$500,6,0),0) -> 0 | H11: =IFERROR(VLOOKUP(E11,'기준가격대장(결산후)'!$A$4:$H$500,7,0),0) -> 0 | I11: =IFERROR(VLOOKUP(E11,'기준가격대장(결산후)'!$A$4:$H$500,8,0),0) -> 0
B12: =IFERROR(VLOOKUP(E12,'기준가격대장(결산후)'!$A$4:$H$500,2,0),0) -> 0 | C12: =IFERROR(VLOOKUP(E12,'기준가격대장(결산후)'!$A$4:$H$500,3,0),0) -> 0 | D12: =IFERROR(VLOOKUP(E12,'기준가격대장(결산후)'!$A$4:$H$500,4,0),0) -> 0 | E12: 107030 | F12: 정기예금 | G12: =IFERROR(VLOOKUP(E12,'기준가격대장(결산후)'!$A$4:$H$500,6,0),0) -> 0 | H12: =IFERROR(VLOOKUP(E12,'기준가격대장(결산후)'!$A$4:$H$500,7,0),0) -> 0 | I12: =IFERROR(VLOOKUP(E12,'기준가격대장(결산후)'!$A$4:$H$500,8,0),0) -> 0
B13: =IFERROR(VLOOKUP(E13,'기준가격대장(결산후)'!$A$4:$H$500,2,0),0) -> 0 | C13: =IFERROR(VLOOKUP(E13,'기준가격대장(결산후)'!$A$4:$H$500,3,0),0) -> 0 | D13: =IFERROR(VLOOKUP(E13,'기준가격대장(결산후)'!$A$4:$H$500,4,0),0) -> 0 | E13: 109030 | F13: REPO | G13: =IFERROR(VLOOKUP(E13,'기준가격대장(결산후)'!$A$4:$H$500,6,0),0) -> 0 | H13: =IFERROR(VLOOKUP(E13,'기준가격대장(결산후)'!$A$4:$H$500,7,0),0) -> 0 | I13: =IFERROR(VLOOKUP(E13,'기준가격대장(결산후)'!$A$4:$H$500,8,0),0) -> 0
B14: =IFERROR(VLOOKUP(E14,'기준가격대장(결산후)'!$A$4:$H$500,2,0),0) -> 106485058475 | C14: =IFERROR(VLOOKUP(E14,'기준가격대장(결산후)'!$A$4:$H$500,3,0),0) -> 33658782896 | D14: =IFERROR(VLOOKUP(E14,'기준가격대장(결산후)'!$A$4:$H$500,4,0),0) -> 73217869377 | E14: 111010 | F14: 상장주식 | G14: =IFERROR(VLOOKUP(E14,'기준가격대장(결산후)'!$A$4:$H$500,6,0),0) -> 0 | H14: =IFERROR(VLOOKUP(E14,'기준가격대장(결산후)'!$A$4:$H$500,7,0),0) -> 391593798 | I14: =IFERROR(VLOOKUP(E14,'기준가격대장(결산후)'!$A$4:$H$500,8,0),0) -> 0
B15: =IFERROR(VLOOKUP(E15,'기준가격대장(결산후)'!$A$4:$H$500,2,0),0) -> 0 | C15: =IFERROR(VLOOKUP(E15,'기준가격대장(결산후)'!$A$4:$H$500,3,0),0) -> 0 | D15: =IFERROR(VLOOKUP(E15,'기준가격대장(결산후)'!$A$4:$H$500,4,0),0) -> 0 | E15: 111030 | F15: 코스닥주식 | G15: =IFERROR(VLOOKUP(E15,'기준가격대장(결산후)'!$A$4:$H$500,6,0),0) -> 0 | H15: =IFERROR(VLOOKUP(E15,'기준가격대장(결산후)'!$A$4:$H$500,7,0),0) -> 0 | I15: =IFERROR(VLOOKUP(E15,'기준가격대장(결산후)'!$A$4:$H$500,8,0),0) -> 0
B16: =IFERROR(VLOOKUP(E16,'기준가격대장(결산후)'!$A$4:$H$500,2,0),0) -> 0 | C16: =IFERROR(VLOOKUP(E16,'기준가격대장(결산후)'!$A$4:$H$500,3,0),0) -> 0 | D16: =IFERROR(VLOOKUP(E16,'기준가격대장(결산후)'!$A$4:$H$500,4,0),0) -> 0 | E16: 111040 | F16: 코넥스주식 | G16: =IFERROR(VLOOKUP(E16,'기준가격대장(결산후)'!$A$4:$H$500,6,0),0) -> 0 | H16: =IFERROR(VLOOKUP(E16,'기준가격대장(결산후)'!$A$4:$H$500,7,0),0) -> 0 | I16: =IFERROR(VLOOKUP(E16,'기준가격대장(결산후)'!$A$4:$H$500,8,0),0) -> 0
B17: =IFERROR(VLOOKUP(E17,'기준가격대장(결산후)'!$A$4:$H$500,2,0),0) -> 0 | C17: =IFERROR(VLOOKUP(E17,'기준가격대장(결산후)'!$A$4:$H$500,3,0),0) -> 0 | D17: =IFERROR(VLOOKUP(E17,'기준가격대장(결산후)'!$A$4:$H$500,4,0),0) -> 0 | E17: 111110 | F17: 외화주식 | G17: =IFERROR(VLOOKUP(E17,'기준가격대장(결산후)'!$A$4:$H$500,6,0),0) -> 0 | H17: =IFERROR(VLOOKUP(E17,'기준가격대장(결산후)'!$A$4:$H$500,7,0),0) -> 0 | I17: =IFERROR(VLOOKUP(E17,'기준가격대장(결산후)'!$A$4:$H$500,8,0),0) -> 0
B18: =IFERROR(VLOOKUP(E18,'기준가격대장(결산후)'!$A$4:$H$500,2,0),0) -> 5368673944 | C18: =IFERROR(VLOOKUP(E18,'기준가격대장(결산후)'!$A$4:$H$500,3,0),0) -> 1765255 | D18: =IFERROR(VLOOKUP(E18,'기준가격대장(결산후)'!$A$4:$H$500,4,0),0) -> 5366908689 | E18: 113010 | F18: 국채 | G18: =IFERROR(VLOOKUP(E18,'기준가격대장(결산후)'!$A$4:$H$500,6,0),0) -> 0 | H18: =IFERROR(VLOOKUP(E18,'기준가격대장(결산후)'!$A$4:$H$500,7,0),0) -> 0 | I18: =IFERROR(VLOOKUP(E18,'기준가격대장(결산후)'!$A$4:$H$500,8,0),0) -> 0
B19: =IFERROR(VLOOKUP(E19,'기준가격대장(결산후)'!$A$4:$H$500,2,0),0) -> 0 | C19: =IFERROR(VLOOKUP(E19,'기준가격대장(결산후)'!$A$4:$H$500,3,0),0) -> 0 | D19: =IFERROR(VLOOKUP(E19,'기준가격대장(결산후)'!$A$4:$H$500,4,0),0) -> 0 | E19: 113030 | F19: 지방채 | G19: =IFERROR(VLOOKUP(E19,'기준가격대장(결산후)'!$A$4:$H$500,6,0),0) -> 0 | H19: =IFERROR(VLOOKUP(E19,'기준가격대장(결산후)'!$A$4:$H$500,7,0),0) -> 0 | I19: =IFERROR(VLOOKUP(E19,'기준가격대장(결산후)'!$A$4:$H$500,8,0),0) -> 0
B20: =IFERROR(VLOOKUP(E20,'기준가격대장(결산후)'!$A$4:$H$500,2,0),0) -> 0 | C20: =IFERROR(VLOOKUP(E20,'기준가격대장(결산후)'!$A$4:$H$500,3,0),0) -> 0 | D20: =IFERROR(VLOOKUP(E20,'기준가격대장(결산후)'!$A$4:$H$500,4,0),0) -> 0 | E20: 113050 | F20: 특수채 | G20: =IFERROR(VLOOKUP(E20,'기준가격대장(결산후)'!$A$4:$H$500,6,0),0) -> 0 | H20: =IFERROR(VLOOKUP(E20,'기준가격대장(결산후)'!$A$4:$H$500,7,0),0) -> 0 | I20: =IFERROR(VLOOKUP(E20,'기준가격대장(결산후)'!$A$4:$H$500,8,0),0) -> 0
B21: =IFERROR(VLOOKUP(E21,'기준가격대장(결산후)'!$A$4:$H$500,2,0),0) -> 0 | C21: =IFERROR(VLOOKUP(E21,'기준가격대장(결산후)'!$A$4:$H$500,3,0),0) -> 0 | D21: =IFERROR(VLOOKUP(E21,'기준가격대장(결산후)'!$A$4:$H$500,4,0),0) -> 0 | E21: 113070 | F21: 통안채 | G21: =IFERROR(VLOOKUP(E21,'기준가격대장(결산후)'!$A$4:$H$500,6,0),0) -> 0 | H21: =IFERROR(VLOOKUP(E21,'기준가격대장(결산후)'!$A$4:$H$500,7,0),0) -> 0 | I21: =IFERROR(VLOOKUP(E21,'기준가격대장(결산후)'!$A$4:$H$500,8,0),0) -> 0
B22: =IFERROR(VLOOKUP(E22,'기준가격대장(결산후)'!$A$4:$H$500,2,0),0) -> 0 | C22: =IFERROR(VLOOKUP(E22,'기준가격대장(결산후)'!$A$4:$H$500,3,0),0) -> 0 | D22: =IFERROR(VLOOKUP(E22,'기준가격대장(결산후)'!$A$4:$H$500,4,0),0) -> 0 | E22: 113090 | F22: 금융채 | G22: =IFERROR(VLOOKUP(E22,'기준가격대장(결산후)'!$A$4:$H$500,6,0),0) -> 0 | H22: =IFERROR(VLOOKUP(E22,'기준가격대장(결산후)'!$A$4:$H$500,7,0),0) -> 0 | I22: =IFERROR(VLOOKUP(E22,'기준가격대장(결산후)'!$A$4:$H$500,8,0),0) -> 0
... B43: =IFERROR(VLOOKUP(E43,'기준가격대장(결산후)'!$A$4:$H$500,2,0),0) -> 584987500 | C43: =IFERROR(VLOOKUP(E43,'기준가격대장(결산후)'!$A$4:$H$500,3,0),0) -> 0 | D43: =IFERROR(VLOOKUP(E43,'기준가격대장(결산후)'!$A$4:$H$500,4,0),0) -> 584987500 | E43: 139410 | F43: 선물미수입금 | G43: =IFERROR(VLOOKUP(E43,'기준가격대장(결산후)'!$A$4:$H$500,6,0),0) -> 0 | H43: =IFERROR(VLOOKUP(E43,'기준가격대장(결산후)'!$A$4:$H$500,7,0),0) -> 0 | I43: =IFERROR(VLOOKUP(E43,'기준가격대장(결산후)'!$A$4:$H$500,8,0),0) -> 0
B44: =IFERROR(VLOOKUP(E44,'기준가격대장(결산후)'!$A$4:$H$500,2,0),0) -> 0 | C44: =IFERROR(VLOOKUP(E44,'기준가격대장(결산후)'!$A$4:$H$500,3,0),0) -> 0 | D44: =IFERROR(VLOOKUP(E44,'기준가격대장(결산후)'!$A$4:$H$500,4,0),0) -> 0 | E44: 139420 | F44: 옵션미수입금 | G44: =IFERROR(VLOOKUP(E44,'기준가격대장(결산후)'!$A$4:$H$500,6,0),0) -> 0 | H44: =IFERROR(VLOOKUP(E44,'기준가격대장(결산후)'!$A$4:$H$500,7,0),0) -> 0 | I44: =IFERROR(VLOOKUP(E44,'기준가격대장(결산후)'!$A$4:$H$500,8,0),0) -> 0 | J44: 추가
B45: =IFERROR(VLOOKUP(E45,'기준가격대장(결산후)'!$A$4:$H$500,2,0),0) -> 0 | C45: =IFERROR(VLOOKUP(E45,'기준가격대장(결산후)'!$A$4:$H$500,3,0),0) -> 0 | D45: =IFERROR(VLOOKUP(E45,'기준가격대장(결산후)'!$A$4:$H$500,4,0),0) -> 0 | E45: 139450 | F45: 국채선물미수입금 | G45: =IFERROR(VLOOKUP(E45,'기준가격대장(결산후)'!$A$4:$H$500,6,0),0) -> 0 | H45: =IFERROR(VLOOKUP(E45,'기준가격대장(결산후)'!$A$4:$H$500,7,0),0) -> 0 | I45: =IFERROR(VLOOKUP(E45,'기준가격대장(결산후)'!$A$4:$H$500,8,0),0) -> 0
B46: =IFERROR(VLOOKUP(E46,'기준가격대장(결산후)'!$A$4:$H$500,2,0),0) -> 0 | C46: =IFERROR(VLOOKUP(E46,'기준가격대장(결산후)'!$A$4:$H$500,3,0),0) -> 0 | D46: =IFERROR(VLOOKUP(E46,'기준가격대장(결산후)'!$A$4:$H$500,4,0),0) -> 0 | E46: 139510 | F46: 달러선물미수입금 | G46: =IFERROR(VLOOKUP(E46,'기준가격대장(결산후)'!$A$4:$H$500,6,0),0) -> 0 | H46: =IFERROR(VLOOKUP(E46,'기준가격대장(결산후)'!$A$4:$H$500,7,0),0) -> 0 | I46: =IFERROR(VLOOKUP(E46,'기준가격대장(결산후)'!$A$4:$H$500,8,0),0) -> 0
B47: =IFERROR(VLOOKUP(E47,'기준가격대장(결산후)'!$A$4:$H$500,2,0),0) -> 455343 | C47: =IFERROR(VLOOKUP(E47,'기준가격대장(결산후)'!$A$4:$H$500,3,0),0) -> 0 | D47: =IFERROR(VLOOKUP(E47,'기준가격대장(결산후)'!$A$4:$H$500,4,0),0) -> 455343 | E47: 139810 | F47: 대차거래미수입금 | G47: =IFERROR(VLOOKUP(E47,'기준가격대장(결산후)'!$A$4:$H$500,6,0),0) -> 0 | H47: =IFERROR(VLOOKUP(E47,'기준가격대장(결산후)'!$A$4:$H$500,7,0),0) -> 0 | I47: =IFERROR(VLOOKUP(E47,'기준가격대장(결산후)'!$A$4:$H$500,8,0),0) -> 0
B48: =IFERROR(VLOOKUP(E48,'기준가격대장(결산후)'!$A$4:$H$500,2,0),0) -> 0 | C48: =IFERROR(VLOOKUP(E48,'기준가격대장(결산후)'!$A$4:$H$500,3,0),0) -> 0 | D48: =IFERROR(VLOOKUP(E48,'기준가격대장(결산후)'!$A$4:$H$500,4,0),0) -> 0 | E48: 139811 | F48: 대차거래미수입금(외화) | G48: =IFERROR(VLOOKUP(E48,'기준가격대장(결산후)'!$A$4:$H$500,6,0),0) -> 0 | H48: =IFERROR(VLOOKUP(E48,'기준가격대장(결산후)'!$A$4:$H$500,7,0),0) -> 0 | I48: =IFERROR(VLOOKUP(E48,'기준가격대장(결산후)'!$A$4:$H$500,8,0),0) -> 0
B49: =IFERROR(VLOOKUP(E49,'기준가격대장(결산후)'!$A$4:$H$500,2,0),0) -> 0 | C49: =IFERROR(VLOOKUP(E49,'기준가격대장(결산후)'!$A$4:$H$500,3,0),0) -> 0 | D49: =IFERROR(VLOOKUP(E49,'기준가격대장(결산후)'!$A$4:$H$500,4,0),0) -> 0 | E49: 139890 | F49: 기타미수입금 | G49: =IFERROR(VLOOKUP(E49,'기준가격대장(결산후)'!$A$4:$H$500,6,0),0) -> 0 | H49: =IFERROR(VLOOKUP(E49,'기준가격대장(결산후)'!$A$4:$H$500,7,0),0) -> 0 | I49: =IFERROR(VLOOKUP(E49,'기준가격대장(결산후)'!$A$4:$H$500,8,0),0) -> 0
B50: =IFERROR(VLOOKUP(E50,'기준가격대장(결산후)'!$A$4:$H$500,2,0),0) -> 221852625 | C50: =IFERROR(VLOOKUP(E50,'기준가격대장(결산후)'!$A$4:$H$500,3,0),0) -> 0 | D50: =IFERROR(VLOOKUP(E50,'기준가격대장(결산후)'!$A$4:$H$500,4,0),0) -> 221852625 | E50: 147010 | F50: 주식미수배당금 | G50: =IFERROR(VLOOKUP(E50,'기준가격대장(결산후)'!$A$4:$H$500,6,0),0) -> 0 | H50: =IFERROR(VLOOKUP(E50,'기준가격대장(결산후)'!$A$4:$H$500,7,0),0) -> 0 | I50: =IFERROR(VLOOKUP(E50,'기준가격대장(결산후)'!$A$4:$H$500,8,0),0) -> 0
B51: =IFERROR(VLOOKUP(E51,'기준가격대장(결산후)'!$A$4:$H$500,2,0),0) -> 0 | C51: =IFERROR(VLOOKUP(E51,'기준가격대장(결산후)'!$A$4:$H$500,3,0),0) -> 0 | D51: =IFERROR(VLOOKUP(E51,'기준가격대장(결산후)'!$A$4:$H$500,4,0),0) -> 0 | E51: 147030 | F51: 외화주식미수배당금 | G51: =IFERROR(VLOOKUP(E51,'기준가격대장(결산후)'!$A$4:$H$500,6,0),0) -> 0 | H51: =IFERROR(VLOOKUP(E51,'기준가격대장(결산후)'!$A$4:$H$500,7,0),0) -> 0 | I51: =IFERROR(VLOOKUP(E51,'기준가격대장(결산후)'!$A$4:$H$500,8,0),0) -> 0
B52: =IFERROR(VLOOKUP(E52,'기준가격대장(결산후)'!$A$4:$H$500,2,0),0) -> 0 | C52: =IFERROR(VLOOKUP(E52,'기준가격대장(결산후)'!$A$4:$H$500,3,0),0) -> 0 | D52: =IFERROR(VLOOKUP(E52,'기준가격대장(결산후)'!$A$4:$H$500,4,0),0) -> 0 | E52: 147050 | F52: 상장펀드미수배당금 | G52: =IFERROR(VLOOKUP(E52,'기준가격대장(결산후)'!$A$4:$H$500,6,0),0) -> 0 | H52: =IFERROR(VLOOKUP(E52,'기준가격대장(결산후)'!$A$4:$H$500,7,0),0) -> 0 | I52: =IFERROR(VLOOKUP(E52,'기준가격대장(결산후)'!$A$4:$H$500,8,0),0) -> 0
B53: =IFERROR(VLOOKUP(E53,'기준가격대장(결산후)'!$A$4:$H$500,2,0),0) -> 0 | C53: =IFERROR(VLOOKUP(E53,'기준가격대장(결산후)'!$A$4:$H$500,3,0),0) -> 0 | D53: =IFERROR(VLOOKUP(E53,'기준가격대장(결산후)'!$A$4:$H$500,4,0),0) -> 0 | E53: 147070 | F53: 수익증권미수배당금 | G53: =IFERROR(VLOOKUP(E53,'기준가격대장(결산후)'!$A$4:$H$500,6,0),0) -> 0 | H53: =IFERROR(VLOOKUP(E53,'기준가격대장(결산후)'!$A$4:$H$500,7,0),0) -> 0 | I53: =IFERROR(VLOOKUP(E53,'기준가격대장(결산후)'!$A$4:$H$500,8,0),0) -> 0
B54: =IFERROR(VLOOKUP(E54,'기준가격대장(결산후)'!$A$4:$H$500,2,0),0) -> 661948 | C54: =IFERROR(VLOOKUP(E54,'기준가격대장(결산후)'!$A$4:$H$500,3,0),0) -> 0 | D54: =IFERROR(VLOOKUP(E54,'기준가격대장(결산후)'!$A$4:$H$500,4,0),0) -> 661948 | E54: 149010 | F54: 채권미수이자 | G54: =IFERROR(VLOOKUP(E54,'기준가격대장(결산후)'!$A$4:$H$500,6,0),0) -> 0 | H54: =IFERROR(VLOOKUP(E54,'기준가격대장(결산후)'!$A$4:$H$500,7,0),0) -> 0 | I54: =IFERROR(VLOOKUP(E54,'기준가격대장(결산후)'!$A$4:$H$500,8,0),0) -> 0
B55: =IFERROR(VLOOKUP(E55,'기준가격대장(결산후)'!$A$4:$H$500,2,0),0) -> 0 | C55: =IFERROR(VLOOKUP(E55,'기준가격대장(결산후)'!$A$4:$H$500,3,0),0) -> 0 | D55: =IFERROR(VLOOKUP(E55,'기준가격대장(결산후)'!$A$4:$H$500,4,0),0) -> 0 | E55: 149030 | F55: 외화채권미수이자 | G55: =IFERROR(VLOOKUP(E55,'기준가격대장(결산후)'!$A$4:$H$500,6,0),0) -> 0 | H55: =IFERROR(VLOOKUP(E55,'기준가격대장(결산후)'!$A$4:$H$500,7,0),0) -> 0 | I55: =IFERROR(VLOOKUP(E55,'기준가격대장(결산후)'!$A$4:$H$500,8,0),0) -> 0
B56: =IFERROR(VLOOKUP(E56,'기준가격대장(결산후)'!$A$4:$H$500,2,0),0) -> 6231172 | C56: =IFERROR(VLOOKUP(E56,'기준가격대장(결산후)'!$A$4:$H$500,3,0),0) -> 0 | D56: =IFERROR(VLOOKUP(E56,'기준가격대장(결산후)'!$A$4:$H$500,4,0),0) -> 6231172 | E56: 149110 | F56: 예금미수이자 | G56: =IFERROR(VLOOKUP(E56,'기준가격대장(결산후)'!$A$4:$H$500,6,0),0) -> 0 | H56: =IFERROR(VLOOKUP(E56,'기준가격대장(결산후)'!$A$4:$H$500,7,0),0) -> 0 | I56: =IFERROR(VLOOKUP(E56,'기준가격대장(결산후)'!$A$4:$H$500,8,0),0) -> 0
... B91: =IFERROR(VLOOKUP(E91,'기준가격대장(결산후)'!$A$4:$H$500,2,0),0) -> 0 | C91: =IFERROR(VLOOKUP(E91,'기준가격대장(결산후)'!$A$4:$H$500,3,0),0) -> 0 | D91: =IFERROR(VLOOKUP(E91,'기준가격대장(결산후)'!$A$4:$H$500,4,0),0) -> 0 | E91: 183611 | F91: 선물평가손익조정(해외-전기) | G91: =IFERROR(VLOOKUP(E91,'기준가격대장(결산후)'!$A$4:$H$500,6,0),0) -> 0 | H91: =IFERROR(VLOOKUP(E91,'기준가격대장(결산후)'!$A$4:$H$500,7,0),0) -> 0 | I91: =IFERROR(VLOOKUP(E91,'기준가격대장(결산후)'!$A$4:$H$500,8,0),0) -> 0
B92: =IFERROR(VLOOKUP(E92,'기준가격대장(결산후)'!$A$4:$H$500,2,0),0) -> 0 | C92: =IFERROR(VLOOKUP(E92,'기준가격대장(결산후)'!$A$4:$H$500,3,0),0) -> 0 | D92: =IFERROR(VLOOKUP(E92,'기준가격대장(결산후)'!$A$4:$H$500,4,0),0) -> 0 | E92: 200000 | F92: 부채합계 | G92: =IFERROR(VLOOKUP(E92,'기준가격대장(결산후)'!$A$4:$H$500,6,0),0) -> 15818638807 | H92: =IFERROR(VLOOKUP(E92,'기준가격대장(결산후)'!$A$4:$H$500,7,0),0) -> 1765257 | I92: =IFERROR(VLOOKUP(E92,'기준가격대장(결산후)'!$A$4:$H$500,8,0),0) -> 15820404064 | K92: 부채검증 | L92: =SUM(I93:I146)=I92 -> TRUE | M92: =SUM(I93:I146)-I92 -> 0
B93: =IFERROR(VLOOKUP(E93,'기준가격대장(결산후)'!$A$4:$H$500,2,0),0) -> 0 | C93: =IFERROR(VLOOKUP(E93,'기준가격대장(결산후)'!$A$4:$H$500,3,0),0) -> 0 | D93: =IFERROR(VLOOKUP(E93,'기준가격대장(결산후)'!$A$4:$H$500,4,0),0) -> 0 | E93: 201050 | F93: 매도REPO | G93: =IFERROR(VLOOKUP(E93,'기준가격대장(결산후)'!$A$4:$H$500,6,0),0) -> 5000000000 | H93: =IFERROR(VLOOKUP(E93,'기준가격대장(결산후)'!$A$4:$H$500,7,0),0) -> 0 | I93: =IFERROR(VLOOKUP(E93,'기준가격대장(결산후)'!$A$4:$H$500,8,0),0) -> 5000000000
B94: =IFERROR(VLOOKUP(E94,'기준가격대장(결산후)'!$A$4:$H$500,2,0),0) -> 0 | C94: =IFERROR(VLOOKUP(E94,'기준가격대장(결산후)'!$A$4:$H$500,3,0),0) -> 0 | D94: =IFERROR(VLOOKUP(E94,'기준가격대장(결산후)'!$A$4:$H$500,4,0),0) -> 0 | E94: 211010 | F94: 미지급상장주식 | G94: =IFERROR(VLOOKUP(E94,'기준가격대장(결산후)'!$A$4:$H$500,6,0),0) -> 0 | H94: =IFERROR(VLOOKUP(E94,'기준가격대장(결산후)'!$A$4:$H$500,7,0),0) -> 0 | I94: =IFERROR(VLOOKUP(E94,'기준가격대장(결산후)'!$A$4:$H$500,8,0),0) -> 0
B95: =IFERROR(VLOOKUP(E95,'기준가격대장(결산후)'!$A$4:$H$500,2,0),0) -> 0 | C95: =IFERROR(VLOOKUP(E95,'기준가격대장(결산후)'!$A$4:$H$500,3,0),0) -> 0 | D95: =IFERROR(VLOOKUP(E95,'기준가격대장(결산후)'!$A$4:$H$500,4,0),0) -> 0 | E95: 213150 | F95: 미지급외화채권 | G95: =IFERROR(VLOOKUP(E95,'기준가격대장(결산후)'!$A$4:$H$500,6,0),0) -> 0 | H95: =IFERROR(VLOOKUP(E95,'기준가격대장(결산후)'!$A$4:$H$500,7,0),0) -> 0 | I95: =IFERROR(VLOOKUP(E95,'기준가격대장(결산후)'!$A$4:$H$500,8,0),0) -> 0
B96: =IFERROR(VLOOKUP(E96,'기준가격대장(결산후)'!$A$4:$H$500,2,0),0) -> 0 | C96: =IFERROR(VLOOKUP(E96,'기준가격대장(결산후)'!$A$4:$H$500,3,0),0) -> 0 | D96: =IFERROR(VLOOKUP(E96,'기준가격대장(결산후)'!$A$4:$H$500,4,0),0) -> 0 | E96: 213170 | F96: 미지급채권 | G96: =IFERROR(VLOOKUP(E96,'기준가격대장(결산후)'!$A$4:$H$500,6,0),0) -> 5366908687 | H96: =IFERROR(VLOOKUP(E96,'기준가격대장(결산후)'!$A$4:$H$500,7,0),0) -> 1765257 | I96: =IFERROR(VLOOKUP(E96,'기준가격대장(결산후)'!$A$4:$H$500,8,0),0) -> 5368673944
...

Sheet C1_정산표
B1: 한빛코스피레버리지증권상장지수투자신탁(주식-파생형)
B2: 45657 | G2: Prepared by : | H2: SJ
B3: 정산표 재계산 | G3: Reviewed by : | H3: MK
J6: 전기보고서숫자 넣어야함
F7: <공고용 BS> | J7: 합계수식걸려있음
B8: 과목 | C8: 제 X (당)기 | E8: 공시여부 | F8: 과목 | G8: 제 X (당)기 | I8: 제 X (전)기 | K8: 주석 번호(자동) | L8: 과목순서(자동)
B9: =F9 -> 자산 | E9: 공시 | F9: 자산
B10: =F10 -> Ⅰ. 운용자산 | C10: =C11++C21+C16+C26 -> 143513794320 | E10: =IF(AND(G10=0,H10=0,I10=0,J10=0),"공시제외","공시") -> 공시 | F10: =L10&". 운용자산" -> Ⅰ. 운용자산 | H10: =G11+G21+G16+G26 -> 138145120376 | J10: 42400001063 | L10: Ⅰ
B11: =F11 -> 1. 현금및예치금 (주석3) | C11: =SUM(C12:C15) -> 7196301321 | E11: =IF(AND(G11=0,H11=0,I11=0,J11=0),"공시제외","공시") -> 공시 | F11: =L11&". 현금및예치금 (주석"&K11&")" -> 1. 현금및예치금 (주석3) | G11: =C11 -> 7196301321 | I11: 2337568068 | K11: =IF(OR(G11>0,I11>0),3,FALSE) -> 3 | L11: =IF(OR(G11>0,I11>0),1,0) -> 1
B12: =F12 -> (1) 현금및현금성자산 | C12: ='통합기준가격대장(결산후)'!B7+'통합기준가격대장(결산후)'!B8 -> 7196301321 | E12: =IF(AND(G12=0,H12=0,I12=0,J12=0),"공시제외","공시") -> 공시 | F12: ="("&L12&") 현금및현금성자산" -> (1) 현금및현금성자산 | G12: =C12 -> 7196301321 | I12: 2246153208 | L12: =IF(OR(G12>0,I12>0),1,0) -> 1
B13: =F13 -> (1) 예치금 | C13: ='통합기준가격대장(결산후)'!B12 -> 0 | E13: =IF(AND(G13=0,H13=0,I13=0,J13=0),"공시제외","공시") -> 공시제외 | F13: ="("&L13&") 예치금" -> (1) 예치금 | G13: =C13 -> 0 | I13: 0 | L13: =IF(OR(G13>0,I13>0),L12+1,L12) -> 1 | N13: (2) 증거금 | Q13: 118923050
B14: =F14 -> (1) 양도성예금증서 | C14: ='통합기준가격대장(결산후)'!B11 -> 0 | E14: =IF(AND(G14=0,H14=0,I14=0,J14=0),"공시제외","공시") -> 공시제외 | F14: ="("&L14&") 양도성예금증서" -> (1) 양도성예금증서 | G14: =C14 -> 0 | I14: 0 | L14: =IF(OR(G14>0,I14>0),L13+1,L13) -> 1 | N14: 2. 대출채권 (주4) | Q14: 1500000000
B15: =F15 -> (2) 증거금 | C15: =SUM('통합기준가격대장(결산후)'!B32:B34) -> 0 | E15: =IF(AND(G15=0,H15=0,I15=0,J15=0),"공시제외","공시") -> 공시 | F15: ="("&L15&") 증거금" -> (2) 증거금 | G15: =C15 -> 0 | I15: 91414860 | L15: =IF(OR(G15>0,I15>0),L14+1,L14) -> 2
B16: =F16 -> 1. 대출채권 (주석3) | C16: =SUM(C17:C20) -> 0 | E16: =IF(AND(G16=0,H16=0,I16=0,J16=0),"공시제외","공시") -> 공시제외 | F16: =L16&". 대출채권 (주석"&K16&")" -> 1. 대출채권 (주석3) | G16: =C16 -> 0 | I16: 0 | K16: =IF(OR(G16>0,I16>0),K11+1,K11) -> 3 | L16: =IF(OR(G16>0,I16>0),L11+1,L11) -> 1 | N16: 3. 유가증권
B17: =F17 -> (0) 콜론 | C17: ='통합기준가격대장(결산후)'!B9 -> 0 | E17: =IF(AND(G17=0,H17=0,I17=0,J17=0),"공시제외","공시") -> 공시제외 | F17: ="("&L17&") 콜론" -> (0) 콜론 | G17: =C17 -> 0 | I17: 0 | L17: =IF(OR(G17>0,I17>0),1,0) -> 0 | N17: (1) 지분증권 (주5)
B18: =F18 -> (0) 환매조건부채권 | C18: ='통합기준가격대장(결산후)'!B13 -> 0 | E18: =IF(AND(G18=0,H18=0,I18=0,J18=0),"공시제외","공시") -> 공시제외 | F18: ="("&L18&") 환매조건부채권" -> (0) 환매조건부채권 | G18: =C18 -> 0 | I18: 0 | L18: =IF(OR(G18>0,I18>0),L17+1,L17) -> 0 | N18: (2) 채무증권 (주6) | Q18: 5340535525
B19: =F19 -> (0) 매입어음 | C19: ='통합기준가격대장(결산후)'!B10 -> 0 | E19: =IF(AND(G19=0,H19=0,I19=0,J19=0),"공시제외","공시") -> 공시제외 | F19: ="("&L19&") 매입어음" -> (0) 매입어음 | G19: =C19 -> 0 | I19: 0 | L19: =IF(OR(G19>0,I19>0),L18+1,L18) -> 0 | N19: (3) 수익증권 (주7) | Q19: 25061088120
B20: =F20 -> (0) 전자단기사채 | E20: =IF(AND(G20=0,H20=0,I20=0,J20=0),"공시제외","공시") -> 공시제외 | F20: ="("&L20&") 전자단기사채" -> (0) 전자단기사채 | G20: =C20 -> 0 | I20: 0 | L20: =IF(OR(G20>0,I20>0),L19+1,L19) -> 0 | N20: II . 기타자산 | R20: 6341002778
B21: =F21 -> 2. 유가증권 | C21: =SUM(C22:C25) -> 136317492999 | E21: =IF(AND(G21=0,H21=0,I21=0,J21=0),"공시제외","공시") -> 공시 | F21: =L21&". 유가증권" -> 2. 유가증권 | G21: =SUM(G22:G25) -> 130948819055 | I21: 40062432995 | L21: =IF(OR(G21>0,I21>0),L16+1,L16) -> 2
B22: =F22 -> (1) 지분증권 (주석4) | C22: =SUM('통합기준가격대장(결산후)'!B14:B17)+'통합기준가격대장(결산후)'!B30 -> 106485058475 | E22: =IF(AND(G22=0,H22=0,I22=0,J22=0),"공시제외","공시") -> 공시 | F22: ="("&L22&") 지분증권 (주석"&K22&")" -> (1) 지분증권 (주석4) | G22: =C22 -> 106485058475 | I22: 28733636115 | K22: =IF(OR(G22>0,I22>0),K16+1,K16) -> 4 | L22: =IF(OR(G22>0,I22>0),1,0) -> 1
B23: =F23 -> (1) 채무증권 (주석4) | C23: =SUM('통합기준가격대장(결산후)'!B18:B24) -> 5368673944 | E23: =IF(AND(G23=0,H23=0,I23=0,J23=0),"공시제외","공시") -> 공시제외 | F23: ="("&L23&") 채무증권 (주석"&K23&")" -> (1) 채무증권 (주석4) | G23: 0 | I23: 0 | K23: =IF(OR(G23>0,I23>0),K22+1,K22) -> 4 | L23: =IF(OR(G23>0,I23>0),L22+1,L22) -> 1
B24: =F24 -> (2) 수익증권 (주석5) | C24: =SUM('통합기준가격대장(결산후)'!B25:B28) -> 24463760580 | E24: =IF(AND(G24=0,H24=0,I24=0,J24=0),"공시제외","공시") -> 공시 | F24: ="("&L24&") 수익증권 (주석"&K24&")" -> (2) 수익증권 (주석5) | G24: =C24 -> 24463760580 | I24: 11328796880 | K24: =IF(OR(G24>0,I24>0),K23+1,K23) -> 5 | L24: =IF(OR(G24>0,I24>0),L23+1,L23) -> 2
B25: (3) 기타유가증권 (주석6) | C25: 0 | E25: =IF(AND(G25=0,H25=0,I25=0,J25=0),"공시제외","공시") -> 공시제외 | F25: ="("&L25&") 기타유가증권 (주석"&K25&")" -> () 기타유가증권 (주석4) | G25: 0 | I25: 0 | K25: =K22 -> 4 | N25: 5. 기타자산 | Q25: 5473242
B26: =F26 -> 2. 파생상품자산 (주석6) | C26: =SUM(C27:C30) -> 0 | E26: =IF(AND(G26=0,H26=0,I26=0,J26=0),"공시제외","공시") -> 공시제외 | F26: =L26&". 파생상품자산 (주석"&K26&")" -> 2. 파생상품자산 (주석6) | G26: =C26 -> 0 | I26: 0 | K26: =IF(OR(G26>0,I26>0,G33>0,I33>0,G42>0,I42>0,G48>0,I48>0),K24+1,K24) -> 6 | L26: =IF(OR(G26>0,I26>0),L21+1,L21) -> 2 | N26: 자 산 총 계 | R26: 103993171846
B27: =F27 -> (0) 외환스왑 | C27: 0 | E27: =IF(AND(G27=0,H27=0,I27=0,J27=0),"공시제외","공시") -> 공시제외 | F27: ="("&L27&") 외환스왑" -> (0) 외환스왑 | G27: =C27 -> 0 | I27: 0 | L27: =IF(OR(G27>0,I27>0),1,0) -> 0 | N27: 부 채
B28: =F28 -> 외화선물 | C28: 0 | E28: =IF(AND(G28=0,H28=0,I28=0,J28=0),"공시제외","공시") -> 공시제외 | F28: 외화선물 | G28: =C28 -> 0 | I28: 0 | N28: Ⅰ. 운용부채 | R28: 10340535525
B29: =F29 -> 옵션매수 | C29: 0 | E29: =IF(AND(G29=0,H29=0,I29=0,J29=0),"공시제외","공시") -> 공시제외 | F29: 옵션매수 | G29: =C29 -> 0 | I29: 0 | N29: 1. 환매조건부매도 (주9) | Q29: 5000000000
B30: =F30 -> (0) 주식워런트증권 | C30: ='통합기준가격대장(결산후)'!B31 -> 0 | E30: =IF(AND(G30=0,H30=0,I30=0,J30=0),"공시제외","공시") -> 공시제외 | F30: ="("&L30&") 주식워런트증권" -> (0) 주식워런트증권 | G30: =C30 -> 0 | I30: 0 | L30: =IF(OR(G30>0,I30>0),L27+1,L27) -> 0 | N30: 2. 매도유가증권 (주10) | Q30: 5340535525
B31: =F31 -> Ⅱ. 기타자산 | C31: =SUM(C32:C36) -> 9675566645 | E31: =IF(AND(G31=0,H31=0,I31=0,J31=0),"공시제외","공시") -> 공시 | F31: =L31&". 기타자산" -> Ⅱ. 기타자산 | H31: =SUM(G32:G36) -> 9675566645 | J31: 128095470 | L31: =IF(OR(H10>0,J10>0),"Ⅱ","Ⅰ") -> Ⅱ
B32: =F32 -> 1. 매도유가증권미수금 | C32: =SUM('통합기준가격대장(결산후)'!B35:B38,'통합기준가격대장(결산후)'!B41:B42) -> 8837106649 | E32: =IF(AND(G32=0,H32=0,I32=0,J32=0),"공시제외","공시") -> 공시 | F32: =L32&". 매도유가증권미수금" -> 1. 매도유가증권미수금 | G32: =C32 -> 8837106649 | I32: 0 | L32: =IF(OR(G32>0,I32>0),1,0) -> 1
B33: =F33 -> 2. 정산미수금 (주석6) | C33: =SUM('통합기준가격대장(결산후)'!B43) -> 584987500 | D33: =C33-C48 -> 584987500 | E33: =IF(AND(G33=0,H33=0,I33=0,J33=0),"공시제외","공시") -> 공시 | F33: =L33&". 정산미수금 (주석"&K33&")" -> 2. 정산미수금 (주석6) | G33: =C33 -> 584987500 | I33: 0 | K33: =IF(OR(G26>0,I26>0,G33>0,I33>0,G42>0,I42>0,G48>0,I48>0),K24+1,K24) -> 6 | L33: =IF(OR(G33>0,I33>0),L32+1,L32) -> 2 | N33: 2 . 정산미지급금 (주8) | Q33: 118650000
B34: =F34 -> 3. 미수이자 | C34: =SUM('통합기준가격대장(결산후)'!B54:B64) -> 31164528 | E34: =IF(AND(G34=0,H34=0,I34=0,J34=0),"공시제외","공시") -> 공시 | F34: =L34&". 미수이자" -> 3. 미수이자 | G34: =C34 -> 31164528 | I34: 6521950 | L34: =IF(OR(G34>0,I34>0),L33+1,L33) -> 3
B35: =F35 -> 4. 미수배당금 | C35: =SUM('통합기준가격대장(결산후)'!B50:B53) -> 221852625 | E35: =IF(AND(G35=0,H35=0,I35=0,J35=0),"공시제외","공시") -> 공시 | F35: =L35&". 미수배당금" -> 4. 미수배당금 | G35: =C35 -> 221852625 | I35: 121342460 | L35: =IF(OR(G35>0,I35>0),L34+1,L34) -> 4
B36: =F36 -> 5. 기타자산 | C36: =SUM('통합기준가격대장(결산후)'!B39:B40,'통합기준가격대장(결산후)'!B47:B49,'통합기준가격대장(결산후)'!B65:B66,'통합기준가격대장(결산후)'!B44) -> 455343 | E36: =IF(AND(G36=0,H36=0,I36=0,J36=0),"공시제외","공시") -> 공시 | F36: =L36&". 기타자산" -> 5. 기타자산 | G36: =C36 -> 455343 | I36: 231060 | L36: =IF(OR(G36>0,I36>0),L35+1,L35) -> 5
B37: =F37 -> 자산 총계 | C37: =C10+C31 -> 153189360965 | D37: ='통합기준가격대장(결산후)'!B6=C37 -> TRUE | E37: 공시 | F37: 자산 총계 | H37: =SUM(H10,H31) -> 147820687021 | J37: 42528096533
B38: =F38 -> 부채 | E38: 공시 | F38: 부채
B39: =F39 -> Ⅰ. 운용부채 | C39: =SUM(C40:C45) -> 10368673944 | E39: =IF(AND(G39=0,H39=0,I39=0,J39=0),"공시제외","공시") -> 공시 | F39: =L39&". 운용부채" -> Ⅰ. 운용부채 | H39: =SUM(G40:G45) -> 5000000000 | J39: 0 | L39: Ⅰ
B40: =F40 -> 1. 환매조건부매도 (주석7) | C40: ='통합기준가격대장(결산후)'!I93 -> 5000000000 | E40: =IF(AND(G40=0,H40=0,I40=0,J40=0),"공시제외","공시") -> 공시 | F40: =L40&". 환매조건부매도 (주석"&K40&")" -> 1. 환매조건부매도 (주석7) | G40: =C40 -> 5000000000 | I40: 0 | K40: =IF(OR(G40>0,I40>0),K42+1,K42) -> 7 | L40: =IF(OR(G40>0,I40>0),1,0) -> 1 | N40: II . 이익잉여금 (주16) | R40: 2882053781
B41: =F41 -> 1. 매도유가증권 (주석7) | C41: =SUM('통합기준가격대장(결산후)'!I94:I97) -> 5368673944 | E41: =IF(AND(G41=0,H41=0,I41=0,J41=0),"공시제외","공시") -> 공시제외 | F41: =L41&". 매도유가증권 (주석"&K41&")" -> 1. 매도유가증권 (주석7) | G41: 0 | I41: 0 | K41: =IF(OR(G41>0,I41>0),K40+1,K40) -> 7 | L41: =IF(OR(G41>0,I41>0),L40+1,L40) -> 1
B42: =F42 -> 1. 파생상품부채 (주석6) | C42: =SUM(C43:C44) -> 0 | E42: =IF(AND(G42=0,H42=0,I42=0,J42=0),"공시제외","공시") -> 공시제외 | F42: =L42&". 파생상품부채 (주석"&K42&")" -> 1. 파생상품부채 (주석6) | G42: =SUM(G43:G45) -> 0 | I42: 0 | K42: =IF(OR(G26>0,I26>0,G33>0,I33>0,G42>0,I42>0,G48>0,I48>0),K24+1,K24) -> 6 | L42: =IF(OR(G42>0,I42>0),L41+1,L41) -> 1 | N42: 전기 : 8,800000좌)
...

Sheet C2_자산부채평가
A1: ='C1_정산표'!B1 -> 한빛코스피레버리지증권상장지수투자신탁(주식-파생형)
A2: ='C1_정산표'!B2 -> 45657 | G2: Prepared by : | H2: ='C1_정산표'!H2 -> SJ
A3: 자산부채확인 | G3: Reviewed by :
A6: 절차 : 자산부채금액이 정산표와 일치하고, 자산수탁조회서와 일치하는지 확인
A8: 결과 : 자산부채명세와 일치함을 확인함
A12: 작성여부 | C12: 구 분 | D12: B/S | E12: 명세서 | F12: 차액
A13: O | C13: 예금 | D13: ='C1_정산표'!C12 -> 7196301321 | E13: =F41 -> 7196301321 | F13: =D13-E13 -> 0 | G13: =SUM(F13:F14) -> 0
A14: O | C14: 예치금 | D14: ='C1_정산표'!C13 -> 0 | F14: =D14-E14 -> 0
A15: O | C15: 위탁증거금 | D15: ='C1_정산표'!C15 -> 0 | E15: =D54 -> 0 | F15: =D15-E15 -> 0 | G15: =SUM(F15:F16) -> 0
A16: O | C16: 현금담보증거금 | D16: 0 | E16: =E60 -> 0 | F16: =D16-E16 -> 0
A17: O | C17: 콜론 | D17: ='C1_정산표'!C17 -> 0 | E17: =E66 -> 0 | F17: =D17-E17 -> 0
A18: O | C18: REPO | D18: ='C1_정산표'!C18 -> 0 | E18: =F74 -> 0 | F18: =D18-E18 -> 0
A19: O | C19: 매입어음 | D19: ='C1_정산표'!G19 -> 0 | E19: =F80 -> 0 | F19: =D19-E19 -> 0
A20: O | C20: 전자단기사채 | D20: ='C1_정산표'!G20 -> 0 | E20: =F86 -> 0 | F20: =D20-E20 -> 0
A21: O | C21: 국채 | D21: ='통합기준가격대장(결산후)'!B18 -> 5368673944 | E21: =SUMIF($E$91:$E$94,C21,$J$91:$J$94) -> 5368673944 | F21: =D21-E21 -> 0 | G21: =SUM(F21:F24) -> 0
A22: O | C22: 특수채 | D22: ='통합기준가격대장(결산후)'!B20 -> 0 | E22: =SUMIF($E$91:$E$94,C22,$J$91:$J$94) -> 0 | F22: =D22-E22 -> 0
A23: O | C23: 통안채 | D23: ='통합기준가격대장(결산후)'!B21 -> 0 | E23: =SUMIF($E$91:$E$94,C23,$J$91:$J$94) -> 0 | F23: =D23-E23 -> 0
A24: O | C24: 회사채 | D24: ='통합기준가격대장(결산후)'!B23 -> 0 | E24: =SUMIF($E$91:$E$94,C24,$J$91:$J$94) -> 0 | F24: =D24-E24 -> 0
A25: O | C25: 상장주식 | D25: ='통합기준가격대장(결산후)'!B14 -> 106485058475 | E25: =F309 -> 106485058475 | F25: =D25-E25 -> 0 | G25: =SUM(F25:F26) -> 0
A26: O | C26: 코스닥주식 | D26: ='통합기준가격대장(결산후)'!B15+'통합기준가격대장(결산후)'!B16 -> 0 | E26: =F356 -> 0 | F26: =D26-E26 -> 0
A27: O | C27: 수익증권 | D27: ='C1_정산표'!C24 -> 24463760580 | E27: =F362 -> 24463760580 | F27: =D27-E27 -> 0
A28: O | C28: 선물미수입금 | D28: ='C1_정산표'!G33 -> 584987500 | E28: =I373 -> 584987500 | F28: =D28-E28 -> 0
A29: O | C29: 선물미지급금 | D29: ='C1_정산표'!G48 -> 0 | E29: =I383 -> 0 | F29: =D29-E29 -> 0
A30: O | C30: 옵션매수 | D30: ='C1_정산표'!G29 -> 0 | E30: =E390 -> 0 | F30: =D30-E30 -> 0
A31: O | C31: 옵션매도 | D31: ='C1_정산표'!G45 -> 0 | E31: =E428 -> 0 | F31: =D31-E31 -> 0
A32: O | C32: 매도유가증권 | D32: ='C1_정산표'!G41 -> 0 | E32: =E434 -> 0 | F32: =D32-E32 -> 0
A33: O | C33: 매도REPO | D33: ='C1_정산표'!G40 -> 5000000000 | E33: =E441 -> 5000000000 | F33: =D33-E33 -> 0
C34: 합 계 | D34: =SUM(D13:D33) -> 149098781820 | E34: =SUM(E13:E33) -> 149098781820 | F34: =SUM(F13:F33) -> 0
A36: =IF($G$13=0,"O","X") -> O | C36: 1. 예금
A37: =IF($G$13=0,"O","X") -> O | C37: 종목명 | D37: 발행률 | E37: 수량 | F37: 취득원가 | G37: 장부가평가액 | H37: 시가평가금액
A38: =IF($G$13=0,"O","X") -> O | C38: [KRW] 예금 | D38: =국내유동명세!E3 -> 2.07 | E38: =SUMIF(국내유동명세!$C:$C,'C2_자산부채평가'!C38,국내유동명세!$K:$K) -> 7196301321 | F38: =SUMIF(국내유동명세!$C:$C,'C2_자산부채평가'!$C38,국내유동명세!$Q:$Q) -> 7196301321 | G38: =SUMIF(국내유동명세!$C:$C,'C2_자산부채평가'!$C38,국내유동명세!$R:$R) -> 7202532493 | H38: =SUMIF(국내유동명세!$C:$C,'C2_자산부채평가'!$C38,국내유동명세!$S:$S) -> 7202532493
A39: =IF($G$13=0,"O","X") -> O
A40: =IF($G$13=0,"O","X") -> O
A41: =IF($G$13=0,"O","X") -> O | F41: =SUM(F38:F40) -> 7196301321
A43: =IF($G$15=0,"O","X") -> O | C43: 1-1. 위탁증거금
A44: =IF($G$15=0,"O","X") -> O | C44: 매매처명 | D44: 원화증거금
A45: =IF($G$15=0,"O","X") -> O | C45: =국내유동명세!C5 -> 0 | D45: =국내유동명세!K5 -> 0
A46: =IF($G$15=0,"O","X") -> O | C46: =국내유동명세!C5 -> 0 | D46: =국내유동명세!K5 -> 0
A47: =IF($G$15=0,"O","X") -> O | C47: =국내유동명세!C6 -> 0 | D47: =국내유동명세!K6 -> 0
A48: =IF($G$15=0,"O","X") -> O | C48: =국내유동명세!C7 -> 0 | D48: =국내유동명세!K7 -> 0
...

Sheet C3_수익
A1: ='C1_정산표'!B1 -> 한빛코스피레버리지증권상장지수투자신탁(주식-파생형)
A2: ='C1_정산표'!B2 -> 45657 | F2: Prepared by : | G2: ='C1_정산표'!H2 -> SJ
A3: 수익 | F3: Reviewed by :
B8: 이자수익 ARP
B13: 이자수익 재계산 | C13: 결론 | D13: =IF(J26<0.05,"적정","부적정") -> 적정
B16: 이자수익구분 | C16: 평균잔액 | D16: 기초이자율 | E16: 기말이자율 | F16: 평균이자율 | G16: 추정이자수익 | H16: 정산표상 이자수익 | I16: 차이 | J16: 차이비율
B17: ='통합기준가격대장(결산후)'!F344 -> 채권수입이자(과세) | C17: =AVERAGE(일별자산내역!J2:J366)-AVERAGE(일별자산내역!K2:K366) -> 44110508 | D17: 0.0336 | E17: 0.0336 | F17: =D17*100/365+E17*265/365 -> 0.0336 | G17: =C17*F17 -> 1482113.1 | H17: ='통합기준가격대장(결산후)'!G344 -> 661948 | I17: =G17-H17 -> 820165.08 | J17: =I17/G17 -> 0.55337551
B18: ='통합기준가격대장(결산후)'!F345 -> 외화채권수입이자(과세) | C18: 0 | D18: 0 | E18: 0 | F18: 0 | G18: =C18*F18 -> 0 | H18: 0 | I18: 0 | J18: 0
B19: ='통합기준가격대장(결산후)'!F346 -> 예금수입이자(과세) | C19: =AVERAGE(일별자산내역!B2:B366)-AVERAGE(일별자산내역!C2:C366) -> 4.0380912e+09 | D19: 0.0253 | E19: =국내유동명세!E3/100 -> 0.0207 | F19: =D19*100/365+E19*265/365 -> 0.021960274 | G19: =C19*F19 -> 88677590 | H19: ='통합기준가격대장(결산후)'!G346 -> 87439722 | I19: =G19-H19 -> 1237868 | J19: =I19/G19 -> 0.013959198
B20: ='통합기준가격대장(결산후)'!F347 -> 콜수입이자(과세) | C20: 0 | D20: 0 | E20: 0 | F20: 0 | G20: =C20*F20 -> 0 | H20: 0 | I20: =G20-H20 -> 0 | J20: 0
B21: ='통합기준가격대장(결산후)'!F348 -> 어음수입이자(과세) | C21: 0 | D21: 0 | E21: 0 | F21: 0 | G21: =C21*F21 -> 0 | H21: 0 | I21: =G21-H21 -> 0 | J21: 0
B22: ='통합기준가격대장(결산후)'!F349 -> 정기예금수입이자(과세) | C22: 0 | D22: 0 | E22: 0 | F22: 0 | G22: 0 | H22: 0 | I22: =G22-H22 -> 0 | J22: 0
B23: ='통합기준가격대장(결산후)'!F350 -> REPO수입이자(과세) | C23: 0 | D23: 0 | E23: 0 | F23: 0 | G23: =C23*F23 -> 0 | H23: 0 | I23: =G23-H23 -> 0 | J23: 0
B24: ='통합기준가격대장(결산후)'!F351 -> 위탁증거금수입이자(과세) | C24: =SUM(국내유동명세!K5:K8) -> 0 | F24: 0 | G24: =C24*F24 -> 0 | H24: 0 | I24: =G24-H24 -> 0 | J24: 0
B25: ='통합기준가격대장(결산후)'!F352 -> 외화예금수입이자(과세) | H25: ='통합기준가격대장(결산후)'!G352 -> 0
B26: 합계 | G26: =SUM(G17:G25) -> 90159703 | H26: =SUM(H17:H25) -> 88101670 | I26: =SUM(I17:I25) -> 2058033.1 | J26: =I26/G26 -> 0.022826529

Sheet 평가액검증(주식)
B1: 한빛코스피레버리지증권상장지수투자신탁(주식-파생형)
B2: ='C1_정산표'!B2 -> 45657 | G2: Prepared by : | H2: ='C1_정산표'!H2 -> SJ
B3: 평가액검증 | G3: Reviewed by :
G9: FALSE의 개수=> | H9: =COUNTIF(H12:H82,0) -> 0 | J9: =COUNTIF(I12:I82,0) -> 0
A10: Column1 | B10: Column2 | C10: Column3 | D10: Column4 | E10: Column5 | F10: Column6 | G10: Column7 | H10: Test 1 | I10: Test 2
A11: 종목 | B11: 종목명 | C11: 상품구분 | D11: 수량 | E11: 취득가액 | F11: 종가 | G11: 평가금액 | H11: 평가금액정확성 | I11: 종가검증 A | J11: 종가검증 B
A12: =국내주식명세!A3 -> KR7001440007 | B12: =국내주식명세!B3 -> 종목002 | C12: =국내주식명세!C3 -> 거래소 | D12: =국내주식명세!D3 -> 5880 | E12: =국내주식명세!E3 -> 91764961 | F12: =국내주식명세!F3 -> 22900 | G12: =국내주식명세!G3 -> 134652000 | H12: =G12=D12*F12 -> TRUE | I12: =INDEX(KRS정보시스템_주식!$A$1:$N$3000,MATCH('평가액검증(주식)'!B12,KRS정보시스템_주식!$B:$B,0),MATCH(KRS정보시스템_주식!$E$1,KRS정보시스템_주식!$1:$1,0)) -> 22900 | J12: =IF(D12=0,"TRUE",IF(F12=I12,"TRUE","FALSE")) -> TRUE
A13: =국내주식명세!A4 -> KR7002380004 | B13: =국내주식명세!B4 -> 종목003 | C13: =국내주식명세!C4 -> 거래소 | D13: =국내주식명세!D4 -> 210 | E13: =국내주식명세!E4 -> 63483000 | F13: =국내주식명세!F4 -> 420500 | G13: =국내주식명세!G4 -> 88305000 | H13: =G13=D13*F13 -> TRUE | I13: =INDEX(KRS정보시스템_주식!$A$1:$N$3000,MATCH('평가액검증(주식)'!B13,KRS정보시스템_주식!$B:$B,0),MATCH(KRS정보시스템_주식!$E$1,KRS정보시스템_주식!$1:$1,0)) -> 420500 | J13: =IF(D13=0,"TRUE",IF(F13=I13,"TRUE","FALSE")) -> TRUE
A14: =국내주식명세!A5 -> KR7003230000 | B14: =국내주식명세!B5 -> 종목004 | C14: =국내주식명세!C5 -> 거래소 | D14: =국내주식명세!D5 -> 210 | E14: =국내주식명세!E5 -> 204090000 | F14: =국내주식명세!F5 -> 1231000 | G14: =국내주식명세!G5 -> 258510000 | H14: =G14=D14*F14 -> TRUE | I14: =INDEX(KRS정보시스템_주식!$A$1:$N$3000,MATCH('평가액검증(주식)'!B14,KRS정보시스템_주식!$B:$B,0),MATCH(KRS정보시스템_주식!$E$1,KRS정보시스템_주식!$1:$1,0)) -> 1231000 | J14: =IF(D14=0,"TRUE",IF(F14=I14,"TRUE","FALSE")) -> TRUE
A15: =국내주식명세!A6 -> KR7003240009 | B15: =국내주식명세!B6 -> 종목005 | C15: =국내주식명세!C6 -> 거래소 | D15: =국내주식명세!D6 -> 35 | E15: =국내주식명세!E6 -> 28063230 | F15: =국내주식명세!F6 -> 762000 | G15: =국내주식명세!G6 -> 26670000 | H15: =G15=D15*F15 -> TRUE | I15: =INDEX(KRS정보시스템_주식!$A$1:$N$3000,MATCH('평가액검증(주식)'!B15,KRS정보시스템_주식!$B:$B,0),MATCH(KRS정보시스템_주식!$E$1,KRS정보시스템_주식!$1:$1,0)) -> 762000 | J15: =IF(D15=0,"TRUE",IF(F15=I15,"TRUE","FALSE")) -> TRUE
A16: =국내주식명세!A7 -> KR7003670007 | B16: =국내주식명세!B7 -> 종목006 | C16: =국내주식명세!C7 -> 거래소 | D16: =국내주식명세!D7 -> 1855 | E16: =국내주식명세!E7 -> 311085250 | F16: =국내주식명세!F7 -> 187000 | G16: =국내주식명세!G7 -> 346885000 | H16: =G16=D16*F16 -> TRUE | I16: =INDEX(KRS정보시스템_주식!$A$1:$N$3000,MATCH('평가액검증(주식)'!B16,KRS정보시스템_주식!$B:$B,0),MATCH(KRS정보시스템_주식!$E$1,KRS정보시스템_주식!$1:$1,0)) -> 187000 | J16: =IF(D16=0,"TRUE",IF(F16=I16,"TRUE","FALSE")) -> TRUE
A17: =국내주식명세!A8 -> KR7004490009 | B17: =국내주식명세!B8 -> 종목007 | C17: =국내주식명세!C8 -> 거래소 | D17: =국내주식명세!D8 -> 420 | E17: =국내주식명세!E8 -> 28544400 | F17: =국내주식명세!F8 -> 62800 | G17: =국내주식명세!G8 -> 26376000 | H17: =G17=D17*F17 -> TRUE | I17: =INDEX(KRS정보시스템_주식!$A$1:$N$3000,MATCH('평가액검증(주식)'!B17,KRS정보시스템_주식!$B:$B,0),MATCH(KRS정보시스템_주식!$E$1,KRS정보시스템_주식!$1:$1,0)) -> 62800 | J17: =IF(D17=0,"TRUE",IF(F17=I17,"TRUE","FALSE")) -> TRUE
A18: =국내주식명세!A9 -> KR7007660004 | B18: =국내주식명세!B9 -> 종목008 | C18: =국내주식명세!C9 -> 거래소 | D18: =국내주식명세!D9 -> 2835 | E18: =국내주식명세!E9 -> 402100300 | F18: =국내주식명세!F9 -> 119200 | G18: =국내주식명세!G9 -> 337932000 | H18: =G18=D18*F18 -> TRUE | I18: =INDEX(KRS정보시스템_주식!$A$1:$N$3000,MATCH('평가액검증(주식)'!B18,KRS정보시스템_주식!$B:$B,0),MATCH(KRS정보시스템_주식!$E$1,KRS정보시스템_주식!$1:$1,0)) -> 119200 | J18: =IF(D18=0,"TRUE",IF(F18=I18,"TRUE","FALSE")) -> TRUE
A19: =국내주식명세!A10 -> KR7009150004 | B19: =국내주식명세!B10 -> 종목009 | C19: =국내주식명세!C10 -> 거래소 | D19: =국내주식명세!D10 -> 2905 | E19: =국내주식명세!E10 -> 492148503 | F19: =국내주식명세!F10 -> 255000 | G19: =국내주식명세!G10 -> 740775000 | H19: =G19=D19*F19 -> TRUE | I19: =INDEX(KRS정보시스템_주식!$A$1:$N$3000,MATCH('평가액검증(주식)'!B19,KRS정보시스템_주식!$B:$B,0),MATCH(KRS정보시스템_주식!$E$1,KRS정보시스템_주식!$1:$1,0)) -> 255000 | J19: =IF(D19=0,"TRUE",IF(F19=I19,"TRUE","FALSE")) -> TRUE
A20: =국내주식명세!A11 -> KR7009540006 | B20: =국내주식명세!B11 -> 종목010 | C20: =국내주식명세!C11 -> 거래소 | D20: =국내주식명세!D11 -> 2450 | E20: =국내주식명세!E11 -> 727251001 | F20: =국내주식명세!F11 -> 407000 | G20: =국내주식명세!G11 -> 997150000 | H20: =G20=D20*F20 -> TRUE | I20: =INDEX(KRS정보시스템_주식!$A$1:$N$3000,MATCH('평가액검증(주식)'!B20,KRS정보시스템_주식!$B:$B,0),MATCH(KRS정보시스템_주식!$E$1,KRS정보시스템_주식!$1:$1,0)) -> 407000 | J20: =IF(D20=0,"TRUE",IF(F20=I20,"TRUE","FALSE")) -> TRUE
A21: =국내주식명세!A12 -> KR7010130003 | B21: =국내주식명세!B12 -> 종목011 | C21: =국내주식명세!C12 -> 거래소 | D21: =국내주식명세!D12 -> 350 | E21: =국내주식명세!E12 -> 363583220 | F21: =국내주식명세!F12 -> 1316000 | G21: =국내주식명세!G12 -> 460600000 | H21: =G21=D21*F21 -> TRUE | I21: =INDEX(KRS정보시스템_주식!$A$1:$N$3000,MATCH('평가액검증(주식)'!B21,KRS정보시스템_주식!$B:$B,0),MATCH(KRS정보시스템_주식!$E$1,KRS정보시스템_주식!$1:$1,0)) -> 1316000 | J21: =IF(D21=0,"TRUE",IF(F21=I21,"TRUE","FALSE")) -> TRUE
A22: =국내주식명세!A13 -> KR7010950004 | B22: =국내주식명세!B13 -> 종목012 | C22: =국내주식명세!C13 -> 거래소 | D22: =국내주식명세!D13 -> 2170 | E22: =국내주식명세!E13 -> 139159001 | F22: =국내주식명세!F13 -> 83000 | G22: =국내주식명세!G13 -> 180110000 | H22: =G22=D22*F22 -> TRUE | I22: =INDEX(KRS정보시스템_주식!$A$1:$N$3000,MATCH('평가액검증(주식)'!B22,KRS정보시스템_주식!$B:$B,0),MATCH(KRS정보시스템_주식!$E$1,KRS정보시스템_주식!$1:$1,0)) -> 83000 | J22: =IF(D22=0,"TRUE",IF(F22=I22,"TRUE","FALSE")) -> TRUE
A23: =국내주식명세!A14 -> KR7017800004 | B23: =국내주식명세!B14 -> 종목013 | C23: =국내주식명세!C14 -> 거래소 | D23: =국내주식명세!D14 -> 1330 | E23: =국내주식명세!E14 -> 86271401 | F23: =국내주식명세!F14 -> 88300 | G23: =국내주식명세!G14 -> 117439000 | H23: =G23=D23*F23 -> TRUE | I23: =INDEX(KRS정보시스템_주식!$A$1:$N$3000,MATCH('평가액검증(주식)'!B23,KRS정보시스템_주식!$B:$B,0),MATCH(KRS정보시스템_주식!$E$1,KRS정보시스템_주식!$1:$1,0)) -> 88300 | J23: =IF(D23=0,"TRUE",IF(F23=I23,"TRUE","FALSE")) -> TRUE
... A42: =국내주식명세!A33 -> KR70126Z0002 | B42: =국내주식명세!B33 -> 종목032 | C42: =국내주식명세!C33 -> 거래소 | D42: =국내주식명세!D33 -> 280 | E42: =국내주식명세!E33 -> 235064992 | F42: =국내주식명세!F33 -> 743000 | G42: =국내주식명세!G33 -> 208040000 | H42: =G42=D42*F42 -> TRUE | I42: =INDEX(KRS정보시스템_주식!$A$1:$N$3000,MATCH('평가액검증(주식)'!B42,KRS정보시스템_주식!$B:$B,0),MATCH(KRS정보시스템_주식!$E$1,KRS정보시스템_주식!$1:$1,0)) -> 743000 | J42: =IF(D42=0,"TRUE",IF(F42=I42,"TRUE","FALSE")) -> TRUE
A43: =국내주식명세!A34 -> KR701888000A | B43: =국내주식명세!B34 -> 종목033 | C43: =국내주식명세!C34 -> 거래소 | D43: =국내주식명세!D34 -> 2529 | E43: =국내주식명세!E34 -> 7157070 | F43: =국내주식명세!F34 -> 2965 | G43: =국내주식명세!G34 -> 7498485 | H43: =G43=D43*F43 -> TRUE | I43: 2965 | J43: =IF(D43=0,"TRUE",IF(F43=I43,"TRUE","FALSE")) -> TRUE
A44: =국내주식명세!A35 -> KR7023530009 | B44: =국내주식명세!B35 -> 종목034 | C44: =국내주식명세!C35 -> 거래소 | D44: =국내주식명세!D35 -> 525 | E44: =국내주식명세!E35 -> 32378487 | F44: =국내주식명세!F35 -> 72500 | G44: =국내주식명세!G35 -> 38062500 | H44: =G44=D44*F44 -> TRUE | I44: =INDEX(KRS정보시스템_주식!$A$1:$N$3000,MATCH('평가액검증(주식)'!B44,KRS정보시스템_주식!$B:$B,0),MATCH(KRS정보시스템_주식!$E$1,KRS정보시스템_주식!$1:$1,0)) -> 72500 | J44: =IF(D44=0,"TRUE",IF(F44=I44,"TRUE","FALSE")) -> TRUE
A45: =국내주식명세!A36 -> KR7028260008 | B45: =국내주식명세!B36 -> 종목035 | C45: =국내주식명세!C36 -> 거래소 | D45: =국내주식명세!D36 -> 5250 | E45: =국내주식명세!E36 -> 845438975 | F45: =국내주식명세!F36 -> 239500 | G45: =국내주식명세!G36 -> 1257375000 | H45: =G45=D45*F45 -> TRUE | I45: =INDEX(KRS정보시스템_주식!$A$1:$N$3000,MATCH('평가액검증(주식)'!B45,KRS정보시스템_주식!$B:$B,0),MATCH(KRS정보시스템_주식!$E$1,KRS정보시스템_주식!$1:$1,0)) -> 239500 | J45: =IF(D45=0,"TRUE",IF(F45=I45,"TRUE","FALSE")) -> TRUE
A46: =국내주식명세!A37 -> KR7032830002 | B46: =국내주식명세!B37 -> 종목036 | C46: =국내주식명세!C37 -> 거래소 | D46: =국내주식명세!D37 -> 4410 | E46: =국내주식명세!E37 -> 513802800 | F46: =국내주식명세!F37 -> 157600 | G46: =국내주식명세!G37 -> 695016000 | H46: =G46=D46*F46 -> TRUE | I46: =INDEX(KRS정보시스템_주식!$A$1:$N$3000,MATCH('평가액검증(주식)'!B46,KRS정보시스템_주식!$B:$B,0),MATCH(KRS정보시스템_주식!$E$1,KRS정보시스템_주식!$1:$1,0)) -> 157600 | J46: =IF(D46=0,"TRUE",IF(F46=I46,"TRUE","FALSE")) -> TRUE
A47: =국내주식명세!A38 -> KR7034220004 | B47: =국내주식명세!B38 -> 종목037 | C47: =국내주식명세!C38 -> 거래소 | D47: =국내주식명세!D38 -> 15190 | E47: =국내주식명세!E38 -> 155584662 | F47: =국내주식명세!F38 -> 11810 | G47: =국내주식명세!G38 -> 179393900 | H47: =G47=D47*F47 -> TRUE | I47: =INDEX(KRS정보시스템_주식!$A$1:$N$3000,MATCH('평가액검증(주식)'!B47,KRS정보시스템_주식!$B:$B,0),MATCH(KRS정보시스템_주식!$E$1,KRS정보시스템_주식!$1:$1,0)) -> 11810 | J47: =IF(D47=0,"TRUE",IF(F47=I47,"TRUE","FALSE")) -> TRUE
A48: =국내주식명세!A39 -> KR7034230003 | B48: =국내주식명세!B39 -> 종목038 | C48: =국내주식명세!C39 -> 거래소 | D48: =국내주식명세!D39 -> 2275 | E48: =국내주식명세!E39 -> 39950500 | F48: =국내주식명세!F39 -> 16550 | G48: =국내주식명세!G39 -> 37651250 | H48: =G48=D48*F48 -> TRUE | I48: =INDEX(KRS정보시스템_주식!$A$1:$N$3000,MATCH('평가액검증(주식)'!B48,KRS정보시스템_주식!$B:$B,0),MATCH(KRS정보시스템_주식!$E$1,KRS정보시스템_주식!$1:$1,0)) -> 16550 | J48: =IF(D48=0,"TRUE",IF(F48=I48,"TRUE","FALSE")) -> TRUE
A49: =국내주식명세!A40 -> KR7042670000 | B49: =국내주식명세!B40 -> 종목039 | C49: =국내주식명세!C40 -> 거래소 | D49: =국내주식명세!D40 -> 760 | E49: =국내주식명세!E40 -> 7135940 | F49: =국내주식명세!F40 -> 13800 | G49: =국내주식명세!G40 -> 10488000 | H49: =G49=D49*F49 -> TRUE | I49: =INDEX(KRS정보시스템_주식!$A$1:$N$3000,MATCH('평가액검증(주식)'!B49,KRS정보시스템_주식!$B:$B,0),MATCH(KRS정보시스템_주식!$E$1,KRS정보시스템_주식!$1:$1,0)) -> 13800 | J49: =IF(D49=0,"TRUE",IF(F49=I49,"TRUE","FALSE")) -> TRUE
A50: =국내주식명세!A41 -> KR7051910008 | B50: =국내주식명세!B41 -> 종목040 | C50: =국내주식명세!C41 -> 거래소 | D50: =국내주식명세!D41 -> 2415 | E50: =국내주식명세!E41 -> 694830001 | F50: =국내주식명세!F41 -> 333000 | G50: =국내주식명세!G41 -> 804195000 | H50: =G50=D50*F50 -> TRUE | I50: =INDEX(KRS정보시스템_주식!$A$1:$N$3000,MATCH('평가액검증(주식)'!B50,KRS정보시스템_주식!$B:$B,0),MATCH(KRS정보시스템_주식!$E$1,KRS정보시스템_주식!$1:$1,0)) -> 333000 | J50: =IF(D50=0,"TRUE",IF(F50=I50,"TRUE","FALSE")) -> TRUE
A51: =국내주식명세!A42 -> KR7068270008 | B51: =국내주식명세!B42 -> 종목041 | C51: =국내주식명세!C42 -> 거래소 | D51: =국내주식명세!D42 -> 8120 | E51: =국내주식명세!E42 -> 1446332762 | F51: =국내주식명세!F42 -> 181000 | G51: =국내주식명세!G42 -> 1469720000 | H51: =G51=D51*F51 -> TRUE | I51: =INDEX(KRS정보시스템_주식!$A$1:$N$3000,MATCH('평가액검증(주식)'!B51,KRS정보시스템_주식!$B:$B,0),MATCH(KRS정보시스템_주식!$E$1,KRS정보시스템_주식!$1:$1,0)) -> 181000 | J51: =IF(D51=0,"TRUE",IF(F51=I51,"TRUE","FALSE")) -> TRUE
A52: =국내주식명세!A43 -> KR7071320006 | B52: =국내주식명세!B43 -> 종목042 | C52: =국내주식명세!C43 -> 거래소 | D52: =국내주식명세!D43 -> 140 | E52: =국내주식명세!E43 -> 12231440 | F52: =국내주식명세!F43 -> 96400 | G52: =국내주식명세!G43 -> 13496000 | H52: =G52=D52*F52 -> TRUE | I52: =INDEX(KRS정보시스템_주식!$A$1:$N$3000,MATCH('평가액검증(주식)'!B52,KRS정보시스템_주식!$B:$B,0),MATCH(KRS정보시스템_주식!$E$1,KRS정보시스템_주식!$1:$1,0)) -> 96400 | J52: =IF(D52=0,"TRUE",IF(F52=I52,"TRUE","FALSE")) -> TRUE
A53: =국내주식명세!A44 -> KR7073240004 | B53: =국내주식명세!B44 -> 종목043 | C53: =국내주식명세!C44 -> 거래소 | D53: =국내주식명세!D44 -> 8295 | E53: =국내주식명세!E44 -> 41897109 | F53: =국내주식명세!F44 -> 5860 | G53: =국내주식명세!G44 -> 48608700 | H53: =G53=D53*F53 -> TRUE | I53: =INDEX(KRS정보시스템_주식!$A$1:$N$3000,MATCH('평가액검증(주식)'!B53,KRS정보시스템_주식!$B:$B,0),MATCH(KRS정보시스템_주식!$E$1,KRS정보시스템_주식!$1:$1,0)) -> 5860 | J53: =IF(D53=0,"TRUE",IF(F53=I53,"TRUE","FALSE")) -> TRUE
A54: =국내주식명세!A45 -> KR7078930005 | B54: =국내주식명세!B45 -> 종목044 | C54: =국내주식명세!C45 -> 거래소 | D54: =국내주식명세!D45 -> 2345 | E54: =국내주식명세!E45 -> 103478152 | F54: =국내주식명세!F45 -> 56300 | G54: =국내주식명세!G45 -> 132023500 | H54: =G54=D54*F54 -> TRUE | I54: =INDEX(KRS정보시스템_주식!$A$1:$N$3000,MATCH('평가액검증(주식)'!B54,KRS정보시스템_주식!$B:$B,0),MATCH(KRS정보시스템_주식!$E$1,KRS정보시스템_주식!$1:$1,0)) -> 56300 | J54: =IF(D54=0,"TRUE",IF(F54=I54,"TRUE","FALSE")) -> TRUE
A55: =국내주식명세!A46 -> KR7093370005 | B55: =국내주식명세!B46 -> 종목045 | C55: =국내주식명세!C46 -> 거래소 | D55: =국내주식명세!D46 -> 2870 | E55: =국내주식명세!E46 -> 17329063 | F55: =국내주식명세!F46 -> 7530 | G55: =국내주식명세!G46 -> 21611100 | H55: =G55=D55*F55 -> TRUE | I55: =INDEX(KRS정보시스템_주식!$A$1:$N$3000,MATCH('평가액검증(주식)'!B55,KRS정보시스템_주식!$B:$B,0),MATCH(KRS정보시스템_주식!$E$1,KRS정보시스템_주식!$1:$1,0)) -> 7530 | J55: =IF(D55=0,"TRUE",IF(F55=I55,"TRUE","FALSE")) -> TRUE
... A107: =국내주식명세!A98 -> KR7454910001 | B107: =국내주식명세!B98 -> 종목097 | C107: =국내주식명세!C98 -> 거래소 | D107: =국내주식명세!D98 -> 1015 | E107: =국내주식명세!E98 -> 61857003 | F107: =국내주식명세!F98 -> 78000 | G107: =국내주식명세!G98 -> 79170000 | H107: =G107=D107*F107 -> TRUE | I107: =INDEX(KRS정보시스템_주식!$A$1:$N$3000,MATCH('평가액검증(주식)'!B107,KRS정보시스템_주식!$B:$B,0),MATCH(KRS정보시스템_주식!$E$1,KRS정보시스템_주식!$1:$1,0)) -> 78000 | J107: =IF(D107=0,"TRUE",IF(F107=I107,"TRUE","FALSE")) -> TRUE
A108: =국내주식명세!A99 -> KR700067000D | B108: =국내주식명세!B99 -> 종목098 | C108: =국내주식명세!C99 -> 거래소 | D108: =국내주식명세!D99 -> 6 | E108: =국내주식명세!E99 -> 3000 | F108: =국내주식명세!F99 -> 47500 | G108: =국내주식명세!G99 -> 285000 | H108: =G108=D108*F108 -> TRUE | I108: 47500 | J108: =IF(D108=0,"TRUE",IF(F108=I108,"TRUE","FALSE")) -> TRUE
A109: =국내주식명세!A100 -> KR7000720003 | B109: =국내주식명세!B100 -> 종목099 | C109: =국내주식명세!C100 -> 거래소 | D109: =국내주식명세!D100 -> 3850 | E109: =국내주식명세!E100 -> 163515001 | F109: =국내주식명세!F100 -> 70100 | G109: =국내주식명세!G100 -> 269885000 | H109: =G109=D109*F109 -> TRUE | I109: =INDEX(KRS정보시스템_주식!$A$1:$N$3000,MATCH('평가액검증(주식)'!B109,KRS정보시스템_주식!$B:$B,0),MATCH(KRS정보시스템_주식!$E$1,KRS정보시스템_주식!$1:$1,0)) -> 70100 | J109: =IF(D109=0,"TRUE",IF(F109=I109,"TRUE","FALSE")) -> TRUE
A110: =국내주식명세!A101 -> KR7000880005 | B110: =국내주식명세!B101 -> 종목100 | C110: =국내주식명세!C101 -> 거래소 | D110: =국내주식명세!D101 -> 1470 | E110: =국내주식명세!E101 -> 72979200 | F110: =국내주식명세!F101 -> 81600 | G110: =국내주식명세!G101 -> 119952000 | H110: =G110=D110*F110 -> TRUE | I110: =INDEX(KRS정보시스템_주식!$A$1:$N$3000,MATCH('평가액검증(주식)'!B110,KRS정보시스템_주식!$B:$B,0),MATCH(KRS정보시스템_주식!$E$1,KRS정보시스템_주식!$1:$1,0)) -> 81600 | J110: =IF(D110=0,"TRUE",IF(F110=I110,"TRUE","FALSE")) -> TRUE
A111: =국내주식명세!A102 -> KR7002030005 | B111: =국내주식명세!B102 -> 종목101 | C111: =국내주식명세!C102 -> 거래소 | D111: =국내주식명세!D102 -> 35 | E111: =국내주식명세!E102 -> 12702090 | F111: =국내주식명세!F102 -> 326500 | G111: =국내주식명세!G102 -> 11427500 | H111: =G111=D111*F111 -> TRUE | I111: =INDEX(KRS정보시스템_주식!$A$1:$N$3000,MATCH('평가액검증(주식)'!B111,KRS정보시스템_주식!$B:$B,0),MATCH(KRS정보시스템_주식!$E$1,KRS정보시스템_주식!$1:$1,0)) -> 326500 | J111: =IF(D111=0,"TRUE",IF(F111=I111,"TRUE","FALSE")) -> TRUE
A112: =국내주식명세!A103 -> KR7004990008 | B112: =국내주식명세!B103 -> 종목102 | C112: =국내주식명세!C103 -> 거래소 | D112: =국내주식명세!D103 -> 1540 | E112: =국내주식명세!E103 -> 38323903 | F112: =국내주식명세!F103 -> 26450 | G112: =국내주식명세!G103 -> 40733000 | H112: =G112=D112*F112 -> TRUE | I112: =INDEX(KRS정보시스템_주식!$A$1:$N$3000,MATCH('평가액검증(주식)'!B112,KRS정보시스템_주식!$B:$B,0),MATCH(KRS정보시스템_주식!$E$1,KRS정보시스템_주식!$1:$1,0)) -> 26450 | J112: =IF(D112=0,"TRUE",IF(F112=I112,"TRUE","FALSE")) -> TRUE
A113: =국내주식명세!A104 -> KR7008730004 | B113: =국내주식명세!B104 -> 종목103 | C113: =국내주식명세!C104 -> 거래소 | D113: =국내주식명세!D104 -> 560 | E113: =국내주식명세!E104 -> 13429600 | F113: =국내주식명세!F104 -> 25800 | G113: =국내주식명세!G104 -> 14448000 | H113: =G113=D113*F113 -> TRUE | I113: =INDEX(KRS정보시스템_주식!$A$1:$N$3000,MATCH('평가액검증(주식)'!B113,KRS정보시스템_주식!$B:$B,0),MATCH(KRS정보시스템_주식!$E$1,KRS정보시스템_주식!$1:$1,0)) -> 25800 | J113: =IF(D113=0,"TRUE",IF(F113=I113,"TRUE","FALSE")) -> TRUE
A114: =국내주식명세!A105 -> KR7009970005 | B114: =국내주식명세!B105 -> 종목104 | C114: =국내주식명세!C105 -> 거래소 | D114: =국내주식명세!D105 -> 280 | E114: =국내주식명세!E105 -> 33441600 | F114: =국내주식명세!F105 -> 191500 | G114: =국내주식명세!G105 -> 53620000 | H114: =G114=D114*F114 -> TRUE | I114: =INDEX(KRS정보시스템_주식!$A$1:$N$3000,MATCH('평가액검증(주식)'!B114,KRS정보시스템_주식!$B:$B,0),MATCH(KRS정보시스템_주식!$E$1,KRS정보시스템_주식!$1:$1,0)) -> 191500 | J114: =IF(D114=0,"TRUE",IF(F114=I114,"TRUE","FALSE")) -> TRUE
...

Sheet KRS정보시스템_주식
A1: 종목코드 | B1: 종목명 | C1: 시장구분 | D1: 소속부 | E1: 종가 | F1: 대비 | G1: 등락률 | H1: 시가 | I1: 고가 | J1: 저가 | K1: 거래량 | L1: 거래대금 | M1: 시가총액 | N1: 상장주식수
A2: 060310 | B2: 3S | C2: KOSDAQ | D2: 벤처기업부 | E2: 1555 | F2: 52 | G2: 3.46 | H2: 1504 | I2: 1605 | J2: 1504 | K2: 480513 | L2: 750346819 | M2: 82506807200 | N2: 53059040
A3: 095570 | B3: AJ네트웍스 | C3: KOSPI | E3: 4660 | F3: 35 | G3: 0.76 | H3: 4625 | I3: 4740 | J3: 4610 | K3: 111113 | L3: 520145365 | M3: 210877856940 | N3: 45252759
A4: 006840 | B4: AK홀딩스 | C4: KOSPI | E4: 8710 | F4: -140 | G4: -1.58 | H4: 8860 | I4: 8860 | J4: 8660 | K4: 5634 | L4: 49295190 | M4: 115386256310 | N4: 13247561
A5: 054620 | B5: APS | C5: KOSDAQ | D5: 중견기업부 | E5: 4060 | F5: -60 | G5: -1.46 | H5: 4090 | I5: 4100 | J5: 3990 | K5: 4278 | L5: 17264175 | M5: 74680537260 | N5: 18394221
A6: 265520 | B6: AP시스템 | C6: KOSDAQ | D6: 우량기업부 | E6: 19370 | F6: -60 | G6: -0.31 | H6: 19410 | I6: 19660 | J6: 19250 | K6: 47653 | L6: 924577775 | M6: 291534402770 | N6: 15050821
A7: 211270 | B7: AP위성 | C7: KOSDAQ | D7: 우량기업부 | E7: 12670 | F7: -30 | G7: -0.24 | H7: 12550 | I7: 12790 | J7: 12300 | K7: 162880 | L7: 2039301055 | M7: 191092791680 | N7: 15082304
A8: 139050 | B8: BF랩스 | C8: KOSDAQ | D8: 관리종목(소속부없음) | E8: 2805 | F8: 0 | G8: 0 | H8: 0 | I8: 0 | J8: 0 | K8: 0 | L8: 0 | M8: 24247965555 | N8: 8644551
A9: 027410 | B9: BGF | C9: KOSPI | E9: 3920 | F9: 25 | G9: 0.64 | H9: 3900 | I9: 3945 | J9: 3870 | K9: 52227 | L9: 204211735 | M9: 375209820720 | N9: 95716791
A10: 282330 | B10: 종목050 | C10: KOSPI | E10: 104800 | F10: -1100 | G10: -1.04 | H10: 105300 | I10: 106500 | J10: 104300 | K10: 35230 | L10: 3689188800 | M10: 1811353348800 | N10: 17283906
A11: 126600 | B11: BGF에코머티리얼즈 | C11: KOSDAQ | D11: 우량기업부 | E11: 3660 | F11: 30 | G11: 0.83 | H11: 3635 | I11: 3680 | J11: 3610 | K11: 56844 | L11: 206895470 | M11: 229726850340 | N11: 62766899
A12: 138930 | B12: 종목155 | C12: KOSPI | E12: 15870 | F12: -170 | G12: -1.06 | H12: 15960 | I12: 16000 | J12: 15840 | K12: 392664 | L12: 6243509760 | M12: 4989927193980 | N12: 314425154
A13: 001460 | B13: BYC | C13: KOSPI | E13: 42100 | F13: 200 | G13: 0.48 | H13: 41900 | I13: 42800 | J13: 41650 | K13: 1967 | L13: 83350300 | M13: 262962915000 | N13: 6246150
A14: 001465 | B14: BYC우 | C14: KOSPI | E14: 24450 | F14: -150 | G14: -0.61 | H14: 24200 | I14: 24900 | J14: 24000 | K14: 824 | L14: 20076850 | M14: 52661632500 | N14: 2153850
A15: 083790 | B15: CG인바이츠 | C15: KOSDAQ | D15: 벤처기업부 | E15: 1487 | F15: 97 | G15: 6.98 | H15: 1390 | I15: 1487 | J15: 1350 | K15: 315331 | L15: 443981945 | M15: 114341648634 | N15: 76894182
A16: 001040 | B16: 종목159 | C16: KOSPI | E16: 172000 | F16: 800 | G16: 0.47 | H16: 170900 | I16: 175600 | J16: 169400 | K16: 122220 | L16: 21001321400 | M16: 5018443656000 | N16: 29176998
A17: 079160 | B17: CJ CGV | C17: KOSPI | E17: 5950 | F17: -50 | G17: -0.83 | H17: 5940 | I17: 6000 | J17: 5780 | K17: 344935 | L17: 2040614265 | M17: 985209901200 | N17: 165581496
A18: 035760 | B18: CJ ENM | C18: KOSDAQ GLOBAL | D18: 중견기업부 | E18: 64600 | F18: 1800 | G18: 2.87 | H18: 62800 | I18: 65100 | J18: 62600 | K18: 54276 | L18: 3496091200 | M18: 1416623348400 | N18: 21929154
A19: 311690 | B19: CJ 바이오사이언스 | C19: KOSDAQ | D19: 기술성장기업부 | E19: 9320 | F19: -320 | G19: -3.32 | H19: 9640 | I19: 9640 | J19: 9280 | K19: 26999 | L19: 252260985 | M19: 121770105840 | N19: 13065462
A20: 00104K | B20: CJ4우(전환) | C20: KOSPI | E20: 152500 | F20: -300 | G20: -0.2 | H20: 152400 | I20: 154900 | J20: 150300 | K20: 7853 | L20: 1194044350 | M20: 644543080000 | N20: 4226512
A21: 000120 | B21: 종목182 | C21: KOSPI | E21: 94600 | F21: 1400 | G21: 1.5 | H21: 93200 | I21: 95300 | J21: 92800 | K21: 49711 | L21: 4686350150 | M21: 2158047742400 | N21: 22812344
A22: 011150 | B22: CJ씨푸드 | C22: KOSPI | E22: 2855 | F22: -45 | G22: -1.55 | H22: 2885 | I22: 2890 | J22: 2810 | K22: 892173 | L22: 2545899199 | M22: 102582356915 | N22: 35930773
A23: 011155 | B23: CJ씨푸드1우 | C23: KOSPI | E23: 16400 | F23: -900 | G23: -5.2 | H23: 16810 | I23: 16810 | J23: 16030 | K23: 9976 | L23: 164257500 | M23: 3280000000 | N23: 200000
A24: 001045 | B24: CJ우 | C24: KOSPI | E24: 89300 | F24: 500 | G24: 0.56 | H24: 88900 | I24: 90300 | J24: 87900 | K24: 1980 | L24: 176597800 | M24: 201837913900 | N24: 2260223
A25: 097950 | B25: 종목017 | C25: KOSPI | E25: 208000 | F25: -1500 | G25: -0.72 | H25: 209500 | I25: 210000 | J25: 207500 | K25: 40062 | L25: 8347646250 | M25: 3131270688000 | N25: 15054186
A26: 097955 | B26: CJ제일제당 우 | C26: KOSPI | E26: 138000 | F26: 300 | G26: 0.22 | H26: 137900 | I26: 138600 | J26: 137500 | K26: 2915 | L26: 402274700 | M26: 183185754000 | N26: 1327433
A27: 051500 | B27: CJ프레시웨이 | C27: KOSDAQ | D27: 우량기업부 | E27: 26750 | F27: -450 | G27: -1.65 | H27: 26900 | I27: 27150 | J27: 26500 | K27: 19476 | L27: 520212900 | M27: 317564925500 | N27: 11871586
A28: 058820 | B28: CMG제약 | C28: KOSDAQ | D28: 중견기업부 | E28: 1858 | F28: -4 | G28: -0.21 | H28: 1855 | I28: 1874 | J28: 1855 | K28: 186467 | L28: 347067717 | M28: 274690776014 | N28: 147842183
A29: 056730 | B29: CNT85 | C29: KOSDAQ | D29: 벤처기업부 | E29: 601 | F29: 1 | G29: 0.17 | H29: 603 | I29: 603 | J29: 593 | K29: 18540 | L29: 11095264 | M29: 44540822786 | N29: 74111186
A30: 000480 | B30: CR홀딩스 | C30: KOSPI | E30: 4835 | F30: -35 | G30: -0.72 | H30: 4870 | I30: 4870 | J30: 4825 | K30: 25752 | L30: 124559746 | M30: 226715519150 | N30: 46890490
A31: 065770 | B31: CS | C31: KOSDAQ | D31: 벤처기업부 | E31: 776 | F31: -2 | G31: -0.26 | H31: 778 | I31: 786 | J31: 775 | K31: 74714 | L31: 58186207 | M31: 15063036880 | N31: 19411130
A32: 083660 | B32: CSA 코스믹 | C32: KOSDAQ | D32: 중견기업부 | E32: 482 | F32: -23 | G32: -4.55 | H32: 504 | I32: 505 | J32: 479 | K32: 508485 | L32: 248132621 | M32: 30283799238 | N32: 62829459
A33: 000590 | B33: CS홀딩스 | C33: KOSPI | E33: 77500 | F33: 100 | G33: 0.13 | H33: 77000 | I33: 77500 | J33: 76500 | K33: 159 | L33: 12260600 | M33: 89472355000 | N33: 1154482
A34: 012030 | B34: DB | C34: KOSPI | E34: 1474 | F34: -1 | G34: -0.07 | H34: 1475 | I34: 1485 | J34: 1461 | K34: 236591 | L34: 349038306 | M34: 296530377242 | N34: 201173933
A35: 477760 | B35: DB금융스팩12호 | C35: KOSDAQ | D35: SPAC(소속부없음) | E35: 2125 | F35: -5 | G35: -0.23 | H35: 2125 | I35: 2130 | J35: 2115 | K35: 1867 | L35: 3972700 | M35: 12410000000 | N35: 5840000
A36: 005830 | B36: 종목161 | C36: KOSPI | E36: 131100 | F36: 2100 | G36: 1.63 | H36: 129300 | I36: 131700 | J36: 128400 | K36: 154324 | L36: 20130430340 | M36: 9281880000000 | N36: 70800000
A37: 016610 | B37: DB증권 | C37: KOSPI | E37: 10850 | F37: 150 | G37: 1.4 | H37: 10700 | I37: 10910 | J37: 10590 | K37: 54682 | L37: 590619390 | M37: 460543320650 | N37: 42446389
A38: 000990 | B38: DB하이텍 | C38: KOSPI | E38: 67600 | F38: 500 | G38: 0.75 | H38: 66800 | I38: 68100 | J38: 66100 | K38: 307807 | L38: 20672310800 | M38: 2940910148800 | N38: 43504588
A39: 099520 | B39: DGI | C39: KOSDAQ | D39: 관리종목(소속부없음) | E39: 1284 | F39: 0 | G39: 0 | H39: 0 | I39: 0 | J39: 0 | K39: 0 | L39: 0 | M39: 58141862016 | N39: 45281824
A40: 000300 | B40: DH오토넥스 | C40: KOSPI | E40: 1984 | F40: 0 | G40: 0 | H40: 0 | I40: 0 | J40: 0 | K40: 0 | L40: 0 | M40: 164422234240 | N40: 82874110
...

Sheet 평가액검증(수익증권)
B1: 한빛코스피레버리지증권상장지수투자신탁(주식-파생형)
B2: ='C1_정산표'!B2 -> 45657 | G2: Prepared by : | H2: ='C1_정산표'!H2 -> SJ
B3: 평가액검증 | G3: Reviewed by :
A5: Column1 | B5: Column2 | C5: Column3 | D5: Column4 | E5: Column5 | F5: Column6 | G5: Column7 | H5: Column8
A6: 종목코드 | B6: 표준코드 | C6: 종목명 | D6: 좌수 | E6: 취득가액 | F6: 기준가격 | G6: 평가금액 | H6: 평가손익 | I6: 평가금액정확성 | J6: 정산가검증 A | K6: 정산가검증 B
A7: =수익증권명세!A3 -> KR7102110004 | B7: =수익증권명세!B3 -> KR7102110004 | C7: =수익증권명세!C3 -> 종목ETF001 | D7: =수익증권명세!G3 -> 401506 | E7: =수익증권명세!K3 -> 23417443577 | F7: =수익증권명세!I3 -> 60930 | G7: =수익증권명세!J3 -> 24463760580 | H7: =수익증권명세!L3 -> 1046317003 | I7: =D7*F7=G7 -> TRUE | J7: =INDEX(KRX정보시스템_ETF!$A$1:$R$2000,MATCH('평가액검증(수익증권)'!C7,KRX정보시스템_ETF!$B:$B,0),MATCH(KRX정보시스템_ETF!$C$1,KRX정보시스템_ETF!$1:$1,0)) -> 60930 | K7: =IF(F7=0,"TRUE",IF(F7=J7,"TRUE","FALSE")) -> TRUE

Sheet KRX정보시스템_ETF
A1: 종목코드 | B1: 종목명 | C1: 종가 | D1: 대비 | E1: 등락률 | F1: 순자산가치(NAV) | G1: 시가 | H1: 고가 | I1: 저가 | J1: 거래량 | K1: 거래대금 | L1: 시가총액 | M1: 순자산총액 | N1: 상장좌수 | O1: 기초지수_지수명 | P1: 기초지수_종가 | Q1: 기초지수_대비 | R1: 기초지수_등락률
A2: 491610 | B2: 1Q CD금리액티브(합성) | C2: 102975 | D2: 35 | E2: 0.03 | F2: 102942.94 | G2: 102960 | H2: 102975 | I2: 102960 | J2: 4996 | K2: 514407646 | L2: 230252100000 | M2: 240165889323 | N2: 2236000 | O2: KIS 하나 CD금리 총수익지수 | P2: 11650.99 | Q2: 2.74 | R2: 0.02
A3: 451060 | B3: 1Q K200액티브 | C3: 19795 | D3: 70 | E3: 0.35 | F3: 19827.18 | G3: 19705 | H3: 19855 | I3: 19675 | J3: 75541 | K3: 1494874190 | L3: 154401000000 | M3: 154652008289 | N3: 7800000 | O3: 코스피 200 | P3: 605.98 | Q3: 0.29 | R3: 0.05
A4: 0103T0 | B4: 1Q K소버린AI | C4: 10005 | D4: -10 | E4: -0.1 | F4: 10012.11 | G4: 10015 | H4: 10035 | I4: 9915 | J4: 152734 | K4: 1522706804 | L4: 33516750000 | M4: 33540578646 | N4: 3350000 | O4: iSelect K소버린AI 지수 | P4: 1974.89 | Q4: -6.34 | R4: -0.32
A5: 463290 | B5: 1Q 단기금융채액티브 | C5: 107215 | D5: 20 | E5: 0.02 | F5: 107216.56 | G5: 107265 | H5: 107265 | I5: 107205 | J5: 1963 | K5: 210470891 | L5: 167255400000 | M5: 167257833015 | N5: 1560000 | O5: MK 머니마켓 지수(총수익) | P5: 14481.79 | Q5: 3.19 | R5: 0.02
A6: 0131W0 | B6: 1Q 단기특수은행채액티브 | C6: 100300 | D6: 35 | E6: 0.03 | F6: 100295.73 | G6: 100295 | H6: 100305 | I6: 100295 | J6: 173 | K6: 17352670 | L6: 105114400000 | M6: 120154278916 | N6: 1048000 | O6: KIS 단기특수은행채 지수(총수익) | P6: 115.11 | Q6: 0.03 | R6: 0.03
A7: 479080 | B7: 1Q 머니마켓액티브 | C7: 52620 | D7: 5 | E7: 0.01 | F7: 52621.36 | G7: 52620 | H7: 52625 | I7: 52620 | J7: 31758 | K7: 1671172152 | L7: 1007462520000 | M7: 1135989981848 | N7: 19146000 | O7: KIS-하나 MMF 지수(총수익) | P7: 118.46 | Q7: 0.03 | R7: 0.03
A8: 0026S0 | B8: 1Q 미국S&P500 | C8: 12085 | D8: 35 | E8: 0.29 | F8: 12071.67 | G8: 12020 | H8: 12085 | I8: 11990 | J8: 330564 | K8: 3976618895 | L8: 188526000000 | M8: 237811821334 | N8: 15600000 | O8: S&P 500 | P8: 6896.24 | Q8: -9.5 | R8: -0.14
A9: 0052S0 | B9: 1Q 미국S&P500미국채혼합50액티브 | C9: 11410 | D9: 35 | E9: 0.31 | F9: 11408.58 | G9: 11365 | H9: 11410 | I9: 11325 | J9: 353743 | K9: 4021983605 | L9: 185983000000 | M9: 192805003698 | N9: 16300000 | O9: S&P 500 and Short-Term Treasury 50/50 Blend Index | P9: 276.17 | Q9: -0.17 | R9: -0.06
